<?xml version="1.0" ?>
<!-- =================================================================================== -->
<!-- |    This document was autogenerated by xacro from base_link_macros.xacro         | -->
<!-- |    EDITING THIS FILE BY HAND IS NOT RECOMMENDED                                 | -->
<!-- =================================================================================== -->
<robot name="navya_bus" xmlns:controller="http://playerstage.sourceforge.net/gazebo/xmlschema/#controller" xmlns:sensor="http://playerstage.sourceforge.net/gazebo/xmlschema/#sensor" xmlns:xacro="http://www.ros.org/wiki/xacro">
  <material name="black">
    <color rgba="0.0 0.0 0.0 1.0"/>
  </material>
  <material name="blue">
    <color rgba="0.0 0.0 0.8 1.0"/>
  </material>
  <material name="green">
    <color rgba="0.0 0.8 0.0 1.0"/>
  </material>
  <material name="grey">
    <color rgba="0.2 0.2 0.2 1.0"/>
  </material>
  <material name="orange">
    <color rgba="1.0 0.423529411765 0.0392156862745 1.0"/>
  </material>
  <material name="brown">
    <color rgba="0.870588235294 0.811764705882 0.764705882353 1.0"/>
  </material>
  <material name="red">
    <color rgba="0.8 0.0 0.0 1.0"/>
  </material>
  <material name="white">
    <color rgba="1.0 1.0 1.0 1.0"/>
  </material>
  <material name="White">
    <color rgba="1 1 1 1"/>
  </material>
  <material name="WhiteTransparent">
    <color rgba="1 1 1 0.3"/>
  </material>
  <material name="Black">
    <color rgba="0.0 0.0 0.0 1.0"/>
  </material>
  <material name="Blue">
    <color rgba="0.0 0.0 0.8 1.0"/>
  </material>
  <material name="BlueTransparent">
    <color rgba="0.0 0.0 0.8 0.7"/>
  </material>
  <material name="Green">
    <color rgba="0.0 0.8 0.0 1.0"/>
  </material>
  <material name="GreenTransparent">
    <color rgba="0.1 0.9 0.05 0.2"/>
  </material>
  <material name="Grey">
    <color rgba="0.2 0.2 0.2 1.0"/>
  </material>
  <material name="DarkGrey">
    <color rgba="0.2 0.2 0.4 1.0"/>
  </material>
  <material name="Orange">
    <color rgba="1.0 0.423529411765 0.0392156862745 1.0"/>
  </material>
  <material name="Brown">
    <color rgba="1 0.3 0.1 1.0"/>
  </material>
  <material name="Wood">
    <color rgba="1 0.3 0.1 1.0"/>
  </material>
  <material name="Red">
    <color rgba="0.8 0.0 0.0 1.0"/>
  </material>
  <!-- in kg-->
  <!-- Size of square 'camera' box -->
  <!-- lights properties-->
  <!-- WE START TO BUILD FROM HERE : ENJOY-->
  <link name="world"/>
  <link name="base_link">
    <visual>
      <material name="White"/>
      <origin rpy=" 0 0 0" xyz="0 0 0.3301"/>
      <geometry>
        <box size="3.4 2.1 0.05"/>
      </geometry>
    </visual>
    <collision>
      <origin rpy=" 0 0 0" xyz="0 0 0.3301"/>
      <geometry>
        <box size="3.4 2.1 0.05"/>
      </geometry>
    </collision>
    <origin rpy="0 0 0" xyz="0 0 0.029335"/>
    <inertial>
      <mass value="600.0"/>
      <inertia ixx="220.625" ixy="0.0" ixz="0.0" iyy="578.125" iyz="0.0" izz="798.5"/>
    </inertial>
  </link>
  <gazebo reference="base_link">
    <material>Gazebo/White</material>
  </gazebo>
  <joint name="fixed" type="fixed">
    <parent link="world"/>
    <child link="base_link"/>
  </joint>
  <!--transmission name="${pos}_link_joint_trans">
      <type>transmission_interface/SimpleTransmission</type>
      <joint name="${pos}_chassis_joint" >
		<hardwareInterface>hardware_interface/EffortJointInterface</hardwareInterface>
      </joint>
      <actuator name="${pos}_link_joint_motor">
        <hardwareInterface>EffortJointInterface</hardwareInterface>
        <mechanicalReduction>1</mechanicalReduction>
      </actuator>
    </transmission-->
  <link name="roof_chassis">
    <visual>
      <material name="Grey"/>
      <!--origin xyz="${x} ${y} ${z}" rpy=" ${r} ${p} ${yaw}"/-->
      <geometry>
        <box size="2.72 2.1 0.05"/>
      </geometry>
    </visual>
    <collision>
      <!--origin xyz="${x} ${y} ${z}" rpy=" ${r} ${p} ${yaw}"/-->
      <geometry>
        <box size="2.72 2.1 0.05"/>
      </geometry>
    </collision>
    <origin rpy="0 0 0" xyz="0 0 0.029335"/>
    <inertial>
      <mass value="180"/>
      <inertia ixx="66.1875" ixy="0.0" ixz="0.0" iyy="111.0135" iyz="0.0" izz="177.126"/>
    </inertial>
  </link>
  <gazebo reference="roof_chassis">
    <material>Gazebo/Grey</material>
  </gazebo>
  <joint name="roof_chassis_joint" type="prismatic">
    <parent link="base_link"/>
    <child link="roof_chassis"/>
    <origin rpy=" 0 0 0" xyz="0 0 2.4551"/>
    <limit effort="100000.00" friction="1000000.0" lower="0" upper="0" velocity="10000.0"/>
    S

  </joint>
  <transmission name="roof_chassis_joint_trans">
    <type>transmission_interface/SimpleTransmission</type>
    <joint name="roof_chassis_joint">
      <hardwareInterface>hardware_interface/EffortJointInterface</hardwareInterface>
    </joint>
    <actuator name="roof_chassis_joint_motor">
      <hardwareInterface>EffortJointInterface</hardwareInterface>
      <mechanicalReduction>1</mechanicalReduction>
    </actuator>
  </transmission>
  <link name="front_axle">
    <visual>
      <material name="Brown"/>
      <origin rpy="0 0 0" xyz="0 0 0"/>
      <geometry>
        <cylinder length="2.2" radius="0.05"/>
      </geometry>
      <material name="Black"/>
    </visual>
    <collision>
      <origin rpy="0 0 0" xyz="0 0 0"/>
      <geometry>
        <cylinder length="2.2" radius="0.05"/>
      </geometry>
    </collision>
    <origin rpy="0 0 0" xyz="0 0 0.0029335"/>
    <inertial>
      <mass value="200.0"/>
      <inertia ixx="80.6666666667" ixy="0.0" ixz="0.0" iyy="0.0" iyz="0.0" izz="1452.0"/>
    </inertial>
  </link>
  <gazebo reference="front_axle">
    <material>Gazebo/Gold</material>
  </gazebo>
  <joint name="front_axle_joint" type="fixed">
    <parent link="base_link"/>
    <child link="front_axle"/>
    <axis xyz="0 0 1"/>
    <origin rpy="1.570796327 0 0" xyz="1.36 0 0.25"/>
    <limit effort="100000.00" friction="100.0" lower="0" upper="0" velocity="0.000"/>
  </joint>
  <!-- Transmission is important to link the joints and the controller -->
  <!--transmission name="${fb}_axle_joint_trans">
      <type>transmission_interface/SimpleTransmission</type>
      <joint name="${fb}_axle_joint" >
		  <hardwareInterface>hardware_interface/EffortJointInterface</hardwareInterface> 
      </joint>
      <actuator name="${fb}_axle_joint_motor">
        <hardwareInterface>EffortJointInterface</hardwareInterface>
        <mechanicalReduction>1</mechanicalReduction>
      </actuator>
    </transmission-->
  <link name="rear_axle">
    <visual>
      <material name="Brown"/>
      <origin rpy="0 0 0" xyz="0 0 0"/>
      <geometry>
        <cylinder length="2.2" radius="0.05"/>
      </geometry>
      <material name="Black"/>
    </visual>
    <collision>
      <origin rpy="0 0 0" xyz="0 0 0"/>
      <geometry>
        <cylinder length="2.2" radius="0.05"/>
      </geometry>
    </collision>
    <origin rpy="0 0 0" xyz="0 0 0.0029335"/>
    <inertial>
      <mass value="200.0"/>
      <inertia ixx="80.6666666667" ixy="0.0" ixz="0.0" iyy="0.0" iyz="0.0" izz="1452.0"/>
    </inertial>
  </link>
  <gazebo reference="rear_axle">
    <material>Gazebo/Gold</material>
  </gazebo>
  <joint name="rear_axle_joint" type="fixed">
    <parent link="base_link"/>
    <child link="rear_axle"/>
    <axis xyz="0 0 1"/>
    <origin rpy="1.570796327 0 0" xyz="-1.36 0 0.25"/>
    <limit effort="100000.00" friction="100.0" lower="0" upper="0" velocity="0.000"/>
  </joint>
  <!-- Transmission is important to link the joints and the controller -->
  <!--transmission name="${fb}_axle_joint_trans">
      <type>transmission_interface/SimpleTransmission</type>
      <joint name="${fb}_axle_joint" >
		  <hardwareInterface>hardware_interface/EffortJointInterface</hardwareInterface> 
      </joint>
      <actuator name="${fb}_axle_joint_motor">
        <hardwareInterface>EffortJointInterface</hardwareInterface>
        <mechanicalReduction>1</mechanicalReduction>
      </actuator>
    </transmission-->
  <link name="front_left_wheel_rim">
    <visual>
      <material name="Brown"/>
      <origin rpy="0 0 0" xyz="0 0 0"/>
      <geometry>
        <cylinder length="0.03" radius="0.1"/>
      </geometry>
      <material name="Black"/>
    </visual>
    <collision>
      <origin rpy="0 0 0" xyz="0 0 0"/>
      <geometry>
        <cylinder length="0.03" radius="0.1"/>
      </geometry>
    </collision>
    <origin rpy="0 0 0" xyz="0 0 0.0029335"/>
    <inertial>
      <mass value="200.0"/>
      <inertia ixx="0.515" ixy="0.0" ixz="0.0" iyy="0.515" iyz="0.0" izz="3.0"/>
    </inertial>
  </link>
  <gazebo reference="front_left_wheel_rim">
    <material>Gazebo/Blue</material>
  </gazebo>
  <joint name="front_left_wheel_rim_joint" type="revolute">
    <parent link="front_axle"/>
    <child link="front_left_wheel_rim"/>
    <origin rpy="0 0 0" xyz="0 0 -1.19891"/>
    <axis rpy="0 {rY} 0" xyz="0 1 0"/>
    <limit effort="10000.00" friction="100.0" lower="-0.523598775668" upper="0.523598775667" velocity="0.00"/>
    <!--limit effort="1000.00" velocity="0.00" friction="100.0" upper="0" lower="0"/-->
    <joint_properties damping="120.0" friction="100.0"/>
  </joint>
  <!-- Transmission is important to link the joints and the controller -->
  <transmission name="front_left_wheel_rim_joint_trans">
    <type>transmission_interface/SimpleTransmission</type>
    <joint name="front_left_wheel_rim_joint">
      <hardwareInterface>hardware_interface/VelocityJointInterface</hardwareInterface>
    </joint>
    <actuator name="front_left_wheel_rim_joint_motor">
      <hardwareInterface>VelocityJointInterface</hardwareInterface>
      <mechanicalReduction>1</mechanicalReduction>
    </actuator>
  </transmission>
  <link name="front_right_wheel_rim">
    <visual>
      <material name="Brown"/>
      <origin rpy="0 0 0" xyz="0 0 0"/>
      <geometry>
        <cylinder length="0.03" radius="0.1"/>
      </geometry>
      <material name="Black"/>
    </visual>
    <collision>
      <origin rpy="0 0 0" xyz="0 0 0"/>
      <geometry>
        <cylinder length="0.03" radius="0.1"/>
      </geometry>
    </collision>
    <origin rpy="0 0 0" xyz="0 0 0.0029335"/>
    <inertial>
      <mass value="200.0"/>
      <inertia ixx="0.515" ixy="0.0" ixz="0.0" iyy="0.515" iyz="0.0" izz="3.0"/>
    </inertial>
  </link>
  <gazebo reference="front_right_wheel_rim">
    <material>Gazebo/Blue</material>
  </gazebo>
  <joint name="front_right_wheel_rim_joint" type="revolute">
    <parent link="front_axle"/>
    <child link="front_right_wheel_rim"/>
    <origin rpy="0 0 0" xyz="0 0 1.19891"/>
    <axis rpy="0 {rY} 0" xyz="0 1 0"/>
    <limit effort="10000.00" friction="100.0" lower="-0.523598775668" upper="0.523598775667" velocity="0.00"/>
    <!--limit effort="1000.00" velocity="0.00" friction="100.0" upper="0" lower="0"/-->
    <joint_properties damping="120.0" friction="100.0"/>
  </joint>
  <!-- Transmission is important to link the joints and the controller -->
  <transmission name="front_right_wheel_rim_joint_trans">
    <type>transmission_interface/SimpleTransmission</type>
    <joint name="front_right_wheel_rim_joint">
      <hardwareInterface>hardware_interface/VelocityJointInterface</hardwareInterface>
    </joint>
    <actuator name="front_right_wheel_rim_joint_motor">
      <hardwareInterface>VelocityJointInterface</hardwareInterface>
      <mechanicalReduction>1</mechanicalReduction>
    </actuator>
  </transmission>
  <link name="rear_left_wheel_rim">
    <visual>
      <material name="Brown"/>
      <origin rpy="0 0 0" xyz="0 0 0"/>
      <geometry>
        <cylinder length="0.03" radius="0.1"/>
      </geometry>
      <material name="Brown"/>
    </visual>
    <collision>
      <origin rpy="0 0 0" xyz="0 0 0"/>
      <geometry>
        <cylinder length="0.03" radius="0.1"/>
      </geometry>
    </collision>
    <origin rpy="0 0 0" xyz="0 0 0.0029335"/>
    <inertial>
      <mass value="200.0"/>
      <inertia ixx="0.515" ixy="0.0" ixz="0.0" iyy="0.515" iyz="0.0" izz="3.0"/>
    </inertial>
  </link>
  <gazebo reference="rear_left_wheel_rim">
    <material>Gazebo/Brown</material>
  </gazebo>
  <joint name="rear_left_wheel_rim_joint" type="revolute">
    <parent link="rear_axle"/>
    <child link="rear_left_wheel_rim"/>
    <origin rpy="0 0 0" xyz="0 0 -1.19891"/>
    <axis rpy="0 1 0" xyz="0 1 0"/>
    <limit effort="1000.00" lower="0" upper="0.004712388981" velocity="0.00"/>
    <joint_properties damping="100.0" friction="100.0"/>
  </joint>
  <!-- Transmission is important to link the joints and the controller -->
  <transmission name="rear_left_wheel_rim_joint_trans">
    <type>transmission_interface/SimpleTransmission</type>
    <joint name="rear_left_wheel_rim_joint">
      <hardwareInterface>hardware_interface/EffortJointInterface</hardwareInterface>
    </joint>
    <actuator name="rear_left_wheel_rim_joint_motor">
      <hardwareInterface>EffortJointInterface</hardwareInterface>
      <mechanicalReduction>1</mechanicalReduction>
    </actuator>
  </transmission>
  <link name="rear_right_wheel_rim">
    <visual>
      <material name="Brown"/>
      <origin rpy="0 0 0" xyz="0 0 0"/>
      <geometry>
        <cylinder length="0.03" radius="0.1"/>
      </geometry>
      <material name="Brown"/>
    </visual>
    <collision>
      <origin rpy="0 0 0" xyz="0 0 0"/>
      <geometry>
        <cylinder length="0.03" radius="0.1"/>
      </geometry>
    </collision>
    <origin rpy="0 0 0" xyz="0 0 0.0029335"/>
    <inertial>
      <mass value="200.0"/>
      <inertia ixx="0.515" ixy="0.0" ixz="0.0" iyy="0.515" iyz="0.0" izz="3.0"/>
    </inertial>
  </link>
  <gazebo reference="rear_right_wheel_rim">
    <material>Gazebo/Brown</material>
  </gazebo>
  <joint name="rear_right_wheel_rim_joint" type="revolute">
    <parent link="rear_axle"/>
    <child link="rear_right_wheel_rim"/>
    <origin rpy="0 0 0" xyz="0 0 1.19891"/>
    <axis rpy="0 1 0" xyz="0 1 0"/>
    <limit effort="1000.00" lower="0" upper="0.004712388981" velocity="0.00"/>
    <joint_properties damping="100.0" friction="100.0"/>
  </joint>
  <!-- Transmission is important to link the joints and the controller -->
  <transmission name="rear_right_wheel_rim_joint_trans">
    <type>transmission_interface/SimpleTransmission</type>
    <joint name="rear_right_wheel_rim_joint">
      <hardwareInterface>hardware_interface/EffortJointInterface</hardwareInterface>
    </joint>
    <actuator name="rear_right_wheel_rim_joint_motor">
      <hardwareInterface>EffortJointInterface</hardwareInterface>
      <mechanicalReduction>1</mechanicalReduction>
    </actuator>
  </transmission>
  <link name="front_left_wheel">
    <visual>
      <material name="Black"/>
      <origin rpy="0 0 0" xyz="0 0 0"/>
      <geometry>
        <!--mesh filename="model://car_wheel/meshes/car_wheel.dae"/-->
        <cylinder length="0.102" radius="0.25"/>
      </geometry>
    </visual>
    <collision>
      <origin rpy="0 0 0" xyz="0 0 0"/>
      <geometry>
        <cylinder length="0.102" radius="0.25"/>
      </geometry>
    </collision>
    <origin rpy="0 0 0" xyz="0 0 0.0029335"/>
    <inertial>
      <mass value="21.0"/>
      <inertia ixx="0.346332" ixy="0.0" ixz="0.0" iyy="0.346332" iyz="0.0" izz="1.96875"/>
    </inertial>
  </link>
  <gazebo reference="front_left_wheel">
    <mu1 value="3000.0"/>
    <mu2 value="2000.0"/>
    <kp value="10000000.0"/>
    <kd value="1.0"/>
    <fdir1 value="1 0 0"/>
    <material>Gazebo/Black</material>
  </gazebo>
  <joint name="front_left_wheel_joint" type="continuous">
    <parent link="front_left_wheel_rim"/>
    <child link="front_left_wheel"/>
    <axis rpy="0 0 0" xyz="0 0 -1"/>
    <origin rpy="0.0 0 0" xyz="0 0 -0.0864"/>
    <limit effort="10" friction="0" velocity="30.0"/>
    <!-- add friction first otherwise, it keeps moving -->
    <dynamics damping="0.7"/>
    <!--joint_properties damping="10000.0" friction="100.0"/-->
  </joint>
  <!-- Transmission is important to link the joints and the controller -->
  <transmission name="front_left_wheel_joint_trans">
    <type>transmission_interface/SimpleTransmission</type>
    <joint name="front_left_wheel_joint">
      <hardwareInterface>hardware_interface/VelocityJointInterface</hardwareInterface>
    </joint>
    <actuator name="front_left_wheel_joint_motor">
      <hardwareInterface>VelocityJointInterface</hardwareInterface>
      <mechanicalReduction>1</mechanicalReduction>
    </actuator>
  </transmission>
  <link name="front_right_wheel">
    <visual>
      <material name="Black"/>
      <origin rpy="0 0 0" xyz="0 0 0"/>
      <geometry>
        <!--mesh filename="model://car_wheel/meshes/car_wheel.dae"/-->
        <cylinder length="0.102" radius="0.25"/>
      </geometry>
    </visual>
    <collision>
      <origin rpy="0 0 0" xyz="0 0 0"/>
      <geometry>
        <cylinder length="0.102" radius="0.25"/>
      </geometry>
    </collision>
    <origin rpy="0 0 0" xyz="0 0 0.0029335"/>
    <inertial>
      <mass value="21.0"/>
      <inertia ixx="0.346332" ixy="0.0" ixz="0.0" iyy="0.346332" iyz="0.0" izz="1.96875"/>
    </inertial>
  </link>
  <gazebo reference="front_right_wheel">
    <mu1 value="3000.0"/>
    <mu2 value="2000.0"/>
    <kp value="10000000.0"/>
    <kd value="1.0"/>
    <fdir1 value="1 0 0"/>
    <material>Gazebo/Black</material>
  </gazebo>
  <joint name="front_right_wheel_joint" type="continuous">
    <parent link="front_right_wheel_rim"/>
    <child link="front_right_wheel"/>
    <axis rpy="0 0 0" xyz="0 0 -1"/>
    <origin rpy="0.0 0 0" xyz="0 0 0.0864"/>
    <limit effort="10" friction="0" velocity="30.0"/>
    <!-- add friction first otherwise, it keeps moving -->
    <dynamics damping="0.7"/>
    <!--joint_properties damping="10000.0" friction="100.0"/-->
  </joint>
  <!-- Transmission is important to link the joints and the controller -->
  <transmission name="front_right_wheel_joint_trans">
    <type>transmission_interface/SimpleTransmission</type>
    <joint name="front_right_wheel_joint">
      <hardwareInterface>hardware_interface/VelocityJointInterface</hardwareInterface>
    </joint>
    <actuator name="front_right_wheel_joint_motor">
      <hardwareInterface>VelocityJointInterface</hardwareInterface>
      <mechanicalReduction>1</mechanicalReduction>
    </actuator>
  </transmission>
  
ro

  <link name="rear_left_wheel">
    <visual>
      <material name="Black"/>
      <origin rpy="0 0 0" xyz="0 0 0"/>
      <geometry>
        <!--mesh filename="model://car_wheel/meshes/car_wheel.dae"/-->
        <cylinder length="0.102" radius="0.25"/>
      </geometry>
    </visual>
    <collision>
      <origin rpy="0 0 0" xyz="0 0 0"/>
      <geometry>
        <cylinder length="0.102" radius="0.25"/>
      </geometry>
    </collision>
    <origin rpy="0 0 0" xyz="0 0 0.0029335"/>
    <inertial>
      <mass value="21.0"/>
      <inertia ixx="0.346332" ixy="0.0" ixz="0.0" iyy="0.346332" iyz="0.0" izz="1.96875"/>
    </inertial>
  </link>
  <gazebo reference="rear_left_wheel">
    <mu1 value="3000.0"/>
    <mu2 value="2000.0"/>
    <kp value="10000000.0"/>
    <kd value="1.0"/>
    <fdir1 value="1 0 0"/>
    <material>Gazebo/Black</material>
  </gazebo>
  <joint name="rear_left_wheel_joint" type="continuous">
    <parent link="rear_left_wheel_rim"/>
    <child link="rear_left_wheel"/>
    <axis rpy="0 0 0" xyz="0 0 -1"/>
    <origin rpy="0.0 0 0" xyz="0 0 -0.0864"/>
    <limit effort="10" friction="0" velocity="30.0"/>
    <!-- add friction first otherwise, it keeps moving -->
    <dynamics damping="0.7"/>
    <!--joint_properties damping="10000.0" friction="100.0"/-->
  </joint>
  <!-- Transmission is important to link the joints and the controller -->
  <transmission name="rear_left_wheel_joint_trans">
    <type>transmission_interface/SimpleTransmission</type>
    <joint name="rear_left_wheel_joint">
      <hardwareInterface>hardware_interface/VelocityJointInterface</hardwareInterface>
    </joint>
    <actuator name="rear_left_wheel_joint_motor">
      <hardwareInterface>VelocityJointInterface</hardwareInterface>
      <mechanicalReduction>1</mechanicalReduction>
    </actuator>
  </transmission>
  <link name="rear_right_wheel">
    <visual>
      <material name="Black"/>
      <origin rpy="0 0 0" xyz="0 0 0"/>
      <geometry>
        <!--mesh filename="model://car_wheel/meshes/car_wheel.dae"/-->
        <cylinder length="0.102" radius="0.25"/>
      </geometry>
    </visual>
    <collision>
      <origin rpy="0 0 0" xyz="0 0 0"/>
      <geometry>
        <cylinder length="0.102" radius="0.25"/>
      </geometry>
    </collision>
    <origin rpy="0 0 0" xyz="0 0 0.0029335"/>
    <inertial>
      <mass value="21.0"/>
      <inertia ixx="0.346332" ixy="0.0" ixz="0.0" iyy="0.346332" iyz="0.0" izz="1.96875"/>
    </inertial>
  </link>
  <gazebo reference="rear_right_wheel">
    <mu1 value="3000.0"/>
    <mu2 value="2000.0"/>
    <kp value="10000000.0"/>
    <kd value="1.0"/>
    <fdir1 value="1 0 0"/>
    <material>Gazebo/Black</material>
  </gazebo>
  <joint name="rear_right_wheel_joint" type="continuous">
    <parent link="rear_right_wheel_rim"/>
    <child link="rear_right_wheel"/>
    <axis rpy="0 0 0" xyz="0 0 -1"/>
    <origin rpy="0.0 0 0" xyz="0 0 0.0864"/>
    <limit effort="10" friction="0" velocity="30.0"/>
    <!-- add friction first otherwise, it keeps moving -->
    <dynamics damping="0.7"/>
    <!--joint_properties damping="10000.0" friction="100.0"/-->
  </joint>
  <!-- Transmission is important to link the joints and the controller -->
  <transmission name="rear_right_wheel_joint_trans">
    <type>transmission_interface/SimpleTransmission</type>
    <joint name="rear_right_wheel_joint">
      <hardwareInterface>hardware_interface/VelocityJointInterface</hardwareInterface>
    </joint>
    <actuator name="rear_right_wheel_joint_motor">
      <hardwareInterface>VelocityJointInterface</hardwareInterface>
      <mechanicalReduction>1</mechanicalReduction>
    </actuator>
  </transmission>
  <!--bh : bonnet, hood-->
  <link name="front_guard">
    <visual>
      <origin rpy="0  0 0" xyz="0 0 0"/>
      <material name="DarkGrey"/>
      <geometry>
        <box size="0.63 2.0 0.02"/>
      </geometry>
    </visual>
    <collision>
      <origin rpy="0 0 0" xyz="0 0 0"/>
      <geometry>
        <box size="0.63 2.0 0.02"/>
      </geometry>
    </collision>
    <origin rpy="0 0 0" xyz="0 0 0.029335"/>
    <inertial>
      <mass value="200.0"/>
      <inertia ixx="66.6733333333" ixy="0.0" ixz="0.0" iyy="6.62166666667" iyz="0.0" izz="73.2816666667"/>
    </inertial>
  </link>
  <gazebo reference="front_guard">
    <material>Gazebo/DarkGrey</material>
  </gazebo>
  <link name="front_guard_camera_link">
    <origin rpy="0 0 0" xyz="0 0 0.029335"/>
    <inertial>
      <mass value="0.1"/>
      <inertia ixx="1.66666666667e-06" ixy="0.0" ixz="0.0" iyy="1.66666666667e-06" iyz="0.0" izz="1.66666666667e-06"/>
    </inertial>
    <collision>
      <origin rpy="0 0 0" xyz="0 0 0"/>
      <geometry>
        <box size="0.02 0.02 0.02"/>
      </geometry>
    </collision>
    <visual>
      <origin rpy="0 0 0" xyz="0 0 0"/>
      <geometry>
        <box size="0.02 0.02 0.02"/>
      </geometry>
      <material name="red"/>
    </visual>
    <origin rpy="0 0 0" xyz="0 0 0.029335"/>
    <inertial>
      <mass value="1e-06"/>
      <inertia ixx="6.66666666667e-11" ixy="0.0" ixz="0.0" iyy="6.66666666667e-11" iyz="0.0" izz="6.66666666667e-11"/>
    </inertial>
  </link>
  <joint name="front_guard_camera_joint" type="revolute">
    <parent link="front_guard"/>
    <child link="front_guard_camera_link"/>
    <origin rpy="0.0 -1.570796327 0.0" xyz="0.08 0 0.0"/>
    <axis xyz="0 1 0"/>
    <limit effort="20" friction="20.0" lower="0" upper="0" velocity="0.11111"/>
  </joint>
  <transmission name="front_guard_camera_joint_trans">
    <type>transmission_interface/SimpleTransmission</type>
    <joint name="front_guard_camera_joint">
      <hardwareInterface>hardware_interface/EffortJointInterface</hardwareInterface>
    </joint>
    <actuator name="front_guard_camera_joint_motor">
      <hardwareInterface>EffortJointInterface</hardwareInterface>
      <mechanicalReduction>1</mechanicalReduction>
    </actuator>
  </transmission>
  <gazebo reference="front_guard_camera_link">
    <sensor name="front_guard_camera" type="camera">
      <update_rate>30.0</update_rate>
      <camera name="front_guard">
        <!--visualize>true</visualize-->
        <horizontal_fov>1.3962634</horizontal_fov>
        <image>
          <width>800</width>
          <height>800</height>
          <format>R8G8B8</format>
        </image>
        <clip>
          <near>0.02</near>
          <far>300</far>
        </clip>
        <noise>
          <type>gaussian</type>
          <!-- Noise is sampled independently per pixel on each frame.
               That pixel's noise value is added to each of its color
               channels, which at that point lie in the range [0,1]. -->
          <mean>0.0</mean>
          <stddev>0.007</stddev>
        </noise>
      </camera>
      <plugin filename="libgazebo_ros_camera.so" name="camera_controller">
        <material>Gazebo/Gold</material>
        <alwaysOn>true</alwaysOn>
        <updateRate>30.0</updateRate>
        <visualize>true</visualize>
        <cameraName>front_guard_camera</cameraName>
        <imageTopicName>image_raw</imageTopicName>
        <cameraInfoTopicName>camera_info</cameraInfoTopicName>
        <frameName>front_guard_camera_link</frameName>
        <robotNamespace>/navya_bus</robotNamespace>
        <hackBaseline>0.07</hackBaseline>
        <distortionK1>0.0</distortionK1>
        <distortionK2>0.0</distortionK2>
        <distortionK3>0.0</distortionK3>
        <distortionT1>0.0</distortionT1>
        <distortionT2>0.0</distortionT2>
      </plugin>
    </sensor>
  </gazebo>
  <joint name="front_guard_laser_joint" type="fixed">
    <axis xyz="0 1 0"/>
    <origin rpy="0.0 -1.570796327 0.0" xyz="0 0.0 0.05"/>
    <limit effort="20" friction="20.0" lower="-3.141592654" upper="3.141592654" velocity="0.11111"/>
    <parent link="front_guard"/>
    <child link="front_guard_laser_link"/>
  </joint>
  <!-- Hokuyo Laser -->
  <link name="front_guard_laser_link">
    <collision>
      <origin rpy="0 0 0" xyz="0 0.0 0.03"/>
      <geometry>
        <box size="0.01 0.01 0.01"/>
      </geometry>
    </collision>
    <visual>
      <origin rpy="0 0 0" xyz="0 0.0 0.03"/>
      <geometry>
        <!--box size="0.01 0.01 0.01"/-->
        <mesh filename="package://navya_description/meshes/hokuyo.dae"/>
      </geometry>
    </visual>
    <origin rpy="0 0 0" xyz="0 0 0.029335"/>
    <inertial>
      <mass value="0.1"/>
      <inertia ixx="1.66666666667e-06" ixy="0.0" ixz="0.0" iyy="1.66666666667e-06" iyz="0.0" izz="1.66666666667e-06"/>
    </inertial>
  </link>
  <gazebo reference="front_guard_laser_link">
    <sensor name="front_guard_hokuyo_sensor" type="ray">
      <!--sensor type="gpu_ray" name="${name}_hokuyo_sensor"-->
      <pose>0 0 0 0 0 0</pose>
      <visualize>true</visualize>
      <update_rate>40</update_rate>
      <ray>
        <scan>
          <horizontal>
            <samples>720</samples>
            <resolution>1</resolution>
            <min_angle>-1.570796</min_angle>
            <max_angle>1.570796</max_angle>
          </horizontal>
        </scan>
        <range>
          <min>0.10</min>
          <max>30.0</max>
          <resolution>0.01</resolution>
        </range>
        <noise>
          <type>gaussian</type>
          <!-- Noise parameters based on published spec for Hokuyo laser
               achieving "+-30mm" accuracy at range < 10m.  A mean of 0.0m and
               stddev of 0.01m will put 99.7% of samples within 0.03m of the true
               reading. -->
          <mean>0.0</mean>
          <stddev>0.01</stddev>
        </noise>
      </ray>
      <plugin filename="libgazebo_ros_laser.so" name="gazebo_ros_head_hokuyo_controller">
        <robotNamespace>/navya_bus</robotNamespace>
        <topicName>front_guard_laser/scan</topicName>
        <frameName>front_guard_laser_link</frameName>
      </plugin>
    </sensor>
  </gazebo>
  <joint name="front_guard_joint" type="prismatic">
    <parent link="base_link"/>
    <child link="front_guard"/>
    <origin rpy="0 1.570796327  0" xyz="1.68 0.0 0.6451"/>
    <limit effort="100.0" friction="120" lower="0" upper="0.0000104719755" velocity="0.01"/>
  </joint>
  <transmission name="front_guard_joint_trans">
    <type>transmission_interface/SimpleTransmission</type>
    <joint name="front_guard_joint">
      <hardwareInterface>hardware_interface/PositionJointInterface</hardwareInterface>
    </joint>
    <actuator name="front_guard_joint_motor">
      <hardwareInterface>PositionJointInterface</hardwareInterface>
      <mechanicalReduction>1</mechanicalReduction>
    </actuator>
  </transmission>
  <!-- Let's work on the rear guard now , there is a further .3m joint elevation on z plane. So, we are adding .5 to the 0.002-->
  <!--xacro:guard fr="rear" parent="base_link" trX="${(-(0.5*chassis_length)+rearguard_height)}"  trY="0.0" 
trZ="${rearguard_width-ch_base_height}" flipY="0.5" flipX="0.5" color="FlatBlack" l="${rearguard_length}" w="${rearguard_width}"
 h="${rearguard_height}" m="${rearguard_mass}"${rearguard_width-ch_base_height} /-->
  <!--bh : bonnet, hood-->
  <link name="rear_guard">
    <!--origin xyz="${trX} ${trY} ${trZ}" rpy="0 ${flipY*M_PI}  ${flipZ*M_PI}"/-->
    <visual>
      <origin rpy="0 0 0" xyz="0.55 0.0 0"/>
      <material name="FlatBlack"/>
      <geometry>
        <box size="1.155 2.0 0.02"/>
      </geometry>
    </visual>
    <collision>
      <origin rpy="0 0 0" xyz="0.55 0.0 0"/>
      <geometry>
        <box size="1.155 2.0 0.02"/>
      </geometry>
    </collision>
    <origin rpy="0 0 0" xyz="0 0 0.029335"/>
    <inertial>
      <mass value="180.0"/>
      <inertia ixx="60.006" ixy="0.0" ixz="0.0" iyy="20.016375" iyz="0.0" izz="80.010375"/>
    </inertial>
  </link>
  <link name="boot_camera_link">
    <origin rpy="0 0 0" xyz="0 0 0.029335"/>
    <inertial>
      <mass value="0.1"/>
      <inertia ixx="1.66666666667e-06" ixy="0.0" ixz="0.0" iyy="1.66666666667e-06" iyz="0.0" izz="1.66666666667e-06"/>
    </inertial>
    <collision>
      <origin rpy="0 0 0" xyz="0 0 0"/>
      <geometry>
        <box size="0.02 0.02 0.02"/>
      </geometry>
    </collision>
    <visual>
      <origin rpy="0 0 0" xyz="0 0 0"/>
      <geometry>
        <box size="0.02 0.02 0.02"/>
      </geometry>
      <material name="red"/>
    </visual>
    <origin rpy="0 0 0" xyz="0 0 0.029335"/>
    <inertial>
      <mass value="1e-06"/>
      <inertia ixx="6.66666666667e-11" ixy="0.0" ixz="0.0" iyy="6.66666666667e-11" iyz="0.0" izz="6.66666666667e-11"/>
    </inertial>
  </link>
  <joint name="boot_camera_joint" type="revolute">
    <parent link="rear_guard"/>
    <child link="boot_camera_link"/>
    <origin rpy="0.0 -1.570796327 0.0" xyz="0.55 0.0 0.05"/>
    <axis xyz="0 1 0"/>
    <limit effort="20" friction="20.0" lower="0" upper="0" velocity="0.11111"/>
  </joint>
  <transmission name="boot_camera_joint_trans">
    <type>transmission_interface/SimpleTransmission</type>
    <joint name="boot_camera_joint">
      <hardwareInterface>hardware_interface/EffortJointInterface</hardwareInterface>
    </joint>
    <actuator name="boot_camera_joint_motor">
      <hardwareInterface>EffortJointInterface</hardwareInterface>
      <mechanicalReduction>1</mechanicalReduction>
    </actuator>
  </transmission>
  <gazebo reference="boot_camera_link">
    <sensor name="boot_camera" type="camera">
      <update_rate>30.0</update_rate>
      <camera name="boot">
        <!--visualize>true</visualize-->
        <horizontal_fov>1.3962634</horizontal_fov>
        <image>
          <width>800</width>
          <height>800</height>
          <format>R8G8B8</format>
        </image>
        <clip>
          <near>0.02</near>
          <far>300</far>
        </clip>
        <noise>
          <type>gaussian</type>
          <!-- Noise is sampled independently per pixel on each frame.
               That pixel's noise value is added to each of its color
               channels, which at that point lie in the range [0,1]. -->
          <mean>0.0</mean>
          <stddev>0.007</stddev>
        </noise>
      </camera>
      <plugin filename="libgazebo_ros_camera.so" name="camera_controller">
        <material>Gazebo/Gold</material>
        <alwaysOn>true</alwaysOn>
        <updateRate>30.0</updateRate>
        <visualize>true</visualize>
        <cameraName>boot_camera</cameraName>
        <imageTopicName>image_raw</imageTopicName>
        <cameraInfoTopicName>camera_info</cameraInfoTopicName>
        <frameName>boot_camera_link</frameName>
        <robotNamespace>/navya_bus</robotNamespace>
        <hackBaseline>0.07</hackBaseline>
        <distortionK1>0.0</distortionK1>
        <distortionK2>0.0</distortionK2>
        <distortionK3>0.0</distortionK3>
        <distortionT1>0.0</distortionT1>
        <distortionT2>0.0</distortionT2>
      </plugin>
    </sensor>
  </gazebo>
  <joint name="boot_laser_joint" type="fixed">
    <axis xyz="0 0 0"/>
    <origin rpy="0.0 -1.570796327 0.0" xyz="0.825 0.0 0.05"/>
    <limit effort="20" friction="20.0" lower="-3.141592654" upper="3.141592654" velocity="0.11111"/>
    <parent link="rear_guard"/>
    <child link="boot_laser_link"/>
  </joint>
  <!-- Hokuyo Laser -->
  <link name="boot_laser_link">
    <collision>
      <origin rpy="0 0 0" xyz="0 0.0 0.03"/>
      <geometry>
        <box size="0.01 0.01 0.01"/>
      </geometry>
    </collision>
    <visual>
      <origin rpy="0 0 0" xyz="0 0.0 0.03"/>
      <geometry>
        <!--box size="0.01 0.01 0.01"/-->
        <mesh filename="package://navya_description/meshes/hokuyo.dae"/>
      </geometry>
    </visual>
    <origin rpy="0 0 0" xyz="0 0 0.029335"/>
    <inertial>
      <mass value="0.1"/>
      <inertia ixx="1.66666666667e-06" ixy="0.0" ixz="0.0" iyy="1.66666666667e-06" iyz="0.0" izz="1.66666666667e-06"/>
    </inertial>
  </link>
  <gazebo reference="boot_laser_link">
    <sensor name="boot_hokuyo_sensor" type="ray">
      <!--sensor type="gpu_ray" name="${name}_hokuyo_sensor"-->
      <pose>0 0 0 0 0 0</pose>
      <visualize>true</visualize>
      <update_rate>40</update_rate>
      <ray>
        <scan>
          <horizontal>
            <samples>720</samples>
            <resolution>1</resolution>
            <min_angle>-1.570796</min_angle>
            <max_angle>1.570796</max_angle>
          </horizontal>
        </scan>
        <range>
          <min>0.10</min>
          <max>30.0</max>
          <resolution>0.01</resolution>
        </range>
        <noise>
          <type>gaussian</type>
          <!-- Noise parameters based on published spec for Hokuyo laser
               achieving "+-30mm" accuracy at range < 10m.  A mean of 0.0m and
               stddev of 0.01m will put 99.7% of samples within 0.03m of the true
               reading. -->
          <mean>0.0</mean>
          <stddev>0.01</stddev>
        </noise>
      </ray>
      <plugin filename="libgazebo_ros_laser.so" name="gazebo_ros_head_hokuyo_controller">
        <robotNamespace>/navya_bus</robotNamespace>
        <topicName>boot_laser/scan</topicName>
        <frameName>boot_laser_link</frameName>
      </plugin>
    </sensor>
  </gazebo>
  <gazebo reference="rear_guard">
    <material>Gazebo/FlatBlack</material>
  </gazebo>
  <joint name="rear_guard_joint" type="revolute">
    <parent link="rear_windscreen"/>
    <child link="rear_guard"/>
    <origin rpy="0 0.308362437905  3.141592654" xyz="-0.55 0.0 0.0"/>
    <axis xyz="0 1 0"/>
    <limit effort="100.0" friction="120" lower="0" upper="0.0000104719755" velocity="0.01"/>
    <!--limit velocity="0.01" friction="120" effort="100.0" lower="0" upper="1.04719755" /-->
  </joint>
  <transmission name="rear_guard_joint_trans">
    <type>transmission_interface/SimpleTransmission</type>
    <joint name="rear_guard_joint">
      <hardwareInterface>hardware_interface/PositionJointInterface</hardwareInterface>
    </joint>
    <actuator name="rear_guard_joint_motor">
      <hardwareInterface>PositionJointInterface</hardwareInterface>
      <mechanicalReduction>1</mechanicalReduction>
    </actuator>
  </transmission>
  <!--Now it is time to add the front guard lights edge offset 3mm (.003)-->
  <!--fb : front, rear ; lr: left, right. type: trafficator, head, break, or rear-->
  <link name="front_left_head_light">
    <origin rpy="0 0 0" xyz="0.01 0.7 0"/>
    <visual>
      <material name="White"/>
      <geometry>
        <box size="0.3 0.05 0.2"/>
      </geometry>
    </visual>
    <collision>
      <geometry>
        <box size="0.3 0.05 0.2"/>
      </geometry>
    </collision>
    <origin rpy="0 0 0" xyz="0 0 0.029335"/>
    <inertial>
      <mass value="1.02"/>
      <inertia ixx="0.0078625" ixy="0.0" ixz="0.0" iyy="0.0036125" iyz="0.0" izz="0.01105"/>
    </inertial>
  </link>
  <gazebo reference="front_left_head_light">
    <material>Gazebo/White</material>
  </gazebo>
  <joint name="front_left_head_light_joint" type="fixed">
    <parent link="front_guard"/>
    <child link="front_left_head_light"/>
    <axis rpy="0 0 0" xyz="0 0 1"/>
    <limit effort="100" lower="0.0000" upper="0.0001" velocity="0"/>
    <origin rpy="1.570796327 0 0" xyz="0.01 0.7 0"/>
  </joint>
  <!-- Transmission is important to link the joints and the controller -->
  <!--transmission name="${fb}_${lr}_${type}_light_joint_trans">
      <type>transmission_interface/SimpleTransmission</type>
      <joint name="${fb}_${lr}_${type}_light_joint" >
		<hardwareInterface>hardware_interface/EffortJointInterface</hardwareInterface>
      </joint>
      <actuator name="${fb}_${lr}_${type}_light_joint_motor">
        <hardwareInterface>EffortJointInterface</hardwareInterface>
        <mechanicalReduction>1</mechanicalReduction>
      </actuator>
    </transmission-->
  <!--fb : front, rear ; lr: left, right. type: trafficator, head, break, or rear-->
  <link name="front_right_head_light">
    <origin rpy="0 0 0" xyz="0.01 -0.7 0"/>
    <visual>
      <material name="White"/>
      <geometry>
        <box size="0.3 0.05 0.2"/>
      </geometry>
    </visual>
    <collision>
      <geometry>
        <box size="0.3 0.05 0.2"/>
      </geometry>
    </collision>
    <origin rpy="0 0 0" xyz="0 0 0.029335"/>
    <inertial>
      <mass value="1.02"/>
      <inertia ixx="0.0078625" ixy="0.0" ixz="0.0" iyy="0.0036125" iyz="0.0" izz="0.01105"/>
    </inertial>
  </link>
  <gazebo reference="front_right_head_light">
    <material>Gazebo/White</material>
  </gazebo>
  <joint name="front_right_head_light_joint" type="fixed">
    <parent link="front_guard"/>
    <child link="front_right_head_light"/>
    <axis rpy="0 0 0" xyz="0 0 1"/>
    <limit effort="100" lower="0.0000" upper="0.0001" velocity="0"/>
    <origin rpy="1.570796327 0 0" xyz="0.01 -0.7 0"/>
  </joint>
  <!-- Transmission is important to link the joints and the controller -->
  <!--transmission name="${fb}_${lr}_${type}_light_joint_trans">
      <type>transmission_interface/SimpleTransmission</type>
      <joint name="${fb}_${lr}_${type}_light_joint" >
		<hardwareInterface>hardware_interface/EffortJointInterface</hardwareInterface>
      </joint>
      <actuator name="${fb}_${lr}_${type}_light_joint_motor">
        <hardwareInterface>EffortJointInterface</hardwareInterface>
        <mechanicalReduction>1</mechanicalReduction>
      </actuator>
    </transmission-->
  <!--fb : front, rear ; lr: left, right. type: trafficator, head, break, or rear-->
  <link name="front_left_trafficator_light">
    <origin rpy="1.570796327 0 0" xyz="0 0 0"/>
    <visual>
      <material name="Orange"/>
      <geometry>
        <sphere radius="0.08"/>
      </geometry>
    </visual>
    <collision>
      <geometry>
        <sphere radius="0.08"/>
      </geometry>
    </collision>
    <origin rpy="0 0 0" xyz="0 0 0.029335"/>
    <inertial>
      <mass value="1.8"/>
      <inertia ixx="0.004608" ixy="0.0" ixz="0.0" iyy="0.004608" iyz="0.0" izz="0.004608"/>
    </inertial>
  </link>
  <joint name="front_left_trafficator_light_joint" type="fixed">
    <parent link="front_guard"/>
    <child link="front_left_trafficator_light"/>
    <origin rpy="0 0 0" xyz="-0.122 -0.9 0"/>
    <axis rpy="0 0 0" xyz="0 0 1"/>
    <limit effort="100" lower="0.0000" upper="0.0001" velocity="0"/>
    <!--joint_properties damping="10.0" friction="10.0"/-->
  </joint>
  <gazebo reference="front_left_trafficator_light">
    <material>Gazebo/Orange</material>
  </gazebo>
  <!-- Transmission is important to link the joints and the controller -->
  <!--transmission name="${fb}_${lr}_{type}_light_joint_trans">
      <type>transmission_interface/SimpleTransmission</type>
      <joint name="${fb}_${lr}_${type}_light_joint" >
		<hardwareInterface>hardware_interface/EffortJointInterface</hardwareInterface>
      </joint>
      <actuator name="${fb}_${lr}_light_joint_motor">
        <hardwareInterface>EffortJointInterface</hardwareInterface>
        <mechanicalReduction>1</mechanicalReduction>
      </actuator>
    </transmission-->
  <!--fb : front, rear ; lr: left, right. type: trafficator, head, break, or rear-->
  <link name="front_right_trafficator_light">
    <origin rpy="1.570796327 0 0" xyz="0 0 0"/>
    <visual>
      <material name="Orange"/>
      <geometry>
        <sphere radius="0.08"/>
      </geometry>
    </visual>
    <collision>
      <geometry>
        <sphere radius="0.08"/>
      </geometry>
    </collision>
    <origin rpy="0 0 0" xyz="0 0 0.029335"/>
    <inertial>
      <mass value="1.8"/>
      <inertia ixx="0.004608" ixy="0.0" ixz="0.0" iyy="0.004608" iyz="0.0" izz="0.004608"/>
    </inertial>
  </link>
  <joint name="front_right_trafficator_light_joint" type="fixed">
    <parent link="front_guard"/>
    <child link="front_right_trafficator_light"/>
    <origin rpy="0 0 0" xyz="-0.122 0.9 0"/>
    <axis rpy="0 0 0" xyz="0 0 1"/>
    <limit effort="100" lower="0.0000" upper="0.0001" velocity="0"/>
    <!--joint_properties damping="10.0" friction="10.0"/-->
  </joint>
  <gazebo reference="front_right_trafficator_light">
    <material>Gazebo/Orange</material>
  </gazebo>
  <!-- Transmission is important to link the joints and the controller -->
  <!--transmission name="${fb}_${lr}_{type}_light_joint_trans">
      <type>transmission_interface/SimpleTransmission</type>
      <joint name="${fb}_${lr}_${type}_light_joint" >
		<hardwareInterface>hardware_interface/EffortJointInterface</hardwareInterface>
      </joint>
      <actuator name="${fb}_${lr}_light_joint_motor">
        <hardwareInterface>EffortJointInterface</hardwareInterface>
        <mechanicalReduction>1</mechanicalReduction>
      </actuator>
    </transmission-->
  <!--fb : front, rear ; lr: left, right. type: trafficator, head, break, or rear-->
  <link name="front_left_fog_light">
    <origin rpy="1.570796327 0 0" xyz="0 0 0"/>
    <visual>
      <material name="Yellow"/>
      <geometry>
        <sphere radius="0.056"/>
      </geometry>
    </visual>
    <collision>
      <geometry>
        <sphere radius="0.056"/>
      </geometry>
    </collision>
    <origin rpy="0 0 0" xyz="0 0 0.029335"/>
    <inertial>
      <mass value="0.052"/>
      <inertia ixx="6.52288e-05" ixy="0.0" ixz="0.0" iyy="6.52288e-05" iyz="0.0" izz="6.52288e-05"/>
    </inertial>
  </link>
  <joint name="front_left_fog_light_joint" type="fixed">
    <parent link="front_guard"/>
    <child link="front_left_fog_light"/>
    <origin rpy="0 0 0" xyz="-0.002 -0.9 0"/>
    <axis rpy="0 0 0" xyz="0 0 1"/>
    <limit effort="100" lower="0.0000" upper="0.0001" velocity="0"/>
    <!--joint_properties damping="10.0" friction="10.0"/-->
  </joint>
  <gazebo reference="front_left_fog_light">
    <material>Gazebo/Yellow</material>
  </gazebo>
  <!-- Transmission is important to link the joints and the controller -->
  <!--transmission name="${fb}_${lr}_{type}_light_joint_trans">
      <type>transmission_interface/SimpleTransmission</type>
      <joint name="${fb}_${lr}_${type}_light_joint" >
		<hardwareInterface>hardware_interface/EffortJointInterface</hardwareInterface>
      </joint>
      <actuator name="${fb}_${lr}_light_joint_motor">
        <hardwareInterface>EffortJointInterface</hardwareInterface>
        <mechanicalReduction>1</mechanicalReduction>
      </actuator>
    </transmission-->
  <!--fb : front, rear ; lr: left, right. type: trafficator, head, break, or rear-->
  <link name="front_right_fog_light">
    <origin rpy="1.570796327 0 0" xyz="0 0 0"/>
    <visual>
      <material name="Yellow"/>
      <geometry>
        <sphere radius="0.056"/>
      </geometry>
    </visual>
    <collision>
      <geometry>
        <sphere radius="0.056"/>
      </geometry>
    </collision>
    <origin rpy="0 0 0" xyz="0 0 0.029335"/>
    <inertial>
      <mass value="0.052"/>
      <inertia ixx="6.52288e-05" ixy="0.0" ixz="0.0" iyy="6.52288e-05" iyz="0.0" izz="6.52288e-05"/>
    </inertial>
  </link>
  <joint name="front_right_fog_light_joint" type="fixed">
    <parent link="front_guard"/>
    <child link="front_right_fog_light"/>
    <origin rpy="0 0 0" xyz="-0.002 0.9 0"/>
    <axis rpy="0 0 0" xyz="0 0 1"/>
    <limit effort="100" lower="0.0000" upper="0.0001" velocity="0"/>
    <!--joint_properties damping="10.0" friction="10.0"/-->
  </joint>
  <gazebo reference="front_right_fog_light">
    <material>Gazebo/Yellow</material>
  </gazebo>
  <!-- Transmission is important to link the joints and the controller -->
  <!--transmission name="${fb}_${lr}_{type}_light_joint_trans">
      <type>transmission_interface/SimpleTransmission</type>
      <joint name="${fb}_${lr}_${type}_light_joint" >
		<hardwareInterface>hardware_interface/EffortJointInterface</hardwareInterface>
      </joint>
      <actuator name="${fb}_${lr}_light_joint_motor">
        <hardwareInterface>EffortJointInterface</hardwareInterface>
        <mechanicalReduction>1</mechanicalReduction>
      </actuator>
    </transmission-->
  <!--Now it is time to add the rear guard lights edge offset 3mm (.003)-->
  <!--fr : front,rear-->
  <link name="left_rear_chassis">
    <visual>
      <material name="Grey"/>
      <origin rpy="0 0 0" xyz="0 0 0"/>
      <geometry>
        <box size="1.36 2.1 0.05"/>
      </geometry>
    </visual>
    <collision>
      <origin rpy="0 0 0" xyz="0 0 0"/>
      <geometry>
        <box size="1.36 2.1 0.05"/>
      </geometry>
    </collision>
    <origin rpy="0 0 0" xyz="0 0 0.029335"/>
    <inertial>
      <mass value="30.0"/>
      <inertia ixx="11.03125" ixy="0.0" ixz="0.0" iyy="4.63025" iyz="0.0" izz="15.649"/>
    </inertial>
  </link>
  <gazebo reference="left_rear_chassis">
    <material>Gazebo/Grey</material>
  </gazebo>
  <joint name="left_rear_chassis_joint" type="fixed">
    <parent link="base_link"/>
    <child link="left_rear_chassis"/>
    <origin rpy="1.570796327 0.0  0" xyz="-1.02 1.025 1.3801"/>
    <limit effort="100.0" friction="120" lower="0" upper="0.0000104719755" velocity="0.01"/>
  </joint>
  <!--transmission name="${lr}_${fb}_chassis_joint_trans">
      <type>transmission_interface/SimpleTransmission</type>
      <joint name="${lr}_${fb}_chassis_joint" >
      <hardwareInterface>hardware_interface/EffortJointInterface</hardwareInterface>
      </joint>
      <actuator name="${lr}_${fb}_chassis_joint_motor">
		  <hardwareInterface>EffortJointInterface</hardwareInterface>
        <mechanicalReduction>1</mechanicalReduction>
      </actuator>
    </transmission-->
  <!--fr : front,rear-->
  <link name="right_rear_chassis">
    <visual>
      <material name="Grey"/>
      <origin rpy="0 0 0" xyz="0 0 0"/>
      <geometry>
        <box size="1.36 2.1 0.05"/>
      </geometry>
    </visual>
    <collision>
      <origin rpy="0 0 0" xyz="0 0 0"/>
      <geometry>
        <box size="1.36 2.1 0.05"/>
      </geometry>
    </collision>
    <origin rpy="0 0 0" xyz="0 0 0.029335"/>
    <inertial>
      <mass value="30.0"/>
      <inertia ixx="11.03125" ixy="0.0" ixz="0.0" iyy="4.63025" iyz="0.0" izz="15.649"/>
    </inertial>
  </link>
  <gazebo reference="right_rear_chassis">
    <material>Gazebo/Grey</material>
  </gazebo>
  <joint name="right_rear_chassis_joint" type="fixed">
    <parent link="base_link"/>
    <child link="right_rear_chassis"/>
    <origin rpy="1.570796327 0.0  0" xyz="-1.02 -1.025 1.3801"/>
    <limit effort="100.0" friction="120" lower="0" upper="0.0000104719755" velocity="0.01"/>
  </joint>
  <!--transmission name="${lr}_${fb}_chassis_joint_trans">
      <type>transmission_interface/SimpleTransmission</type>
      <joint name="${lr}_${fb}_chassis_joint" >
      <hardwareInterface>hardware_interface/EffortJointInterface</hardwareInterface>
      </joint>
      <actuator name="${lr}_${fb}_chassis_joint_motor">
		  <hardwareInterface>EffortJointInterface</hardwareInterface>
        <mechanicalReduction>1</mechanicalReduction>
      </actuator>
    </transmission-->
  <!--fb : front, rear ; lr: left, right. type: trafficator, head, break, or rear-->
  <link name="rear_left_rear_light">
    <origin rpy="1.570796327 0 0" xyz="0 0 0"/>
    <visual>
      <material name="Turquoise"/>
      <geometry>
        <sphere radius="0.1"/>
      </geometry>
    </visual>
    <collision>
      <geometry>
        <sphere radius="0.1"/>
      </geometry>
    </collision>
    <origin rpy="0 0 0" xyz="0 0 0.029335"/>
    <inertial>
      <mass value="0.815"/>
      <inertia ixx="0.00326" ixy="0.0" ixz="0.0" iyy="0.00326" iyz="0.0" izz="0.00326"/>
    </inertial>
  </link>
  <joint name="rear_left_rear_light_joint" type="fixed">
    <parent link="rear_guard"/>
    <child link="rear_left_rear_light"/>
    <origin rpy="0 0 0" xyz="0.75 0.9 0"/>
    <axis rpy="0 0 0" xyz="0 0 1"/>
    <limit effort="100" lower="0.0000" upper="0.0001" velocity="0"/>
    <!--joint_properties damping="10.0" friction="10.0"/-->
  </joint>
  <gazebo reference="rear_left_rear_light">
    <material>Gazebo/Turquoise</material>
  </gazebo>
  <!-- Transmission is important to link the joints and the controller -->
  <!--transmission name="${fb}_${lr}_{type}_light_joint_trans">
      <type>transmission_interface/SimpleTransmission</type>
      <joint name="${fb}_${lr}_${type}_light_joint" >
		<hardwareInterface>hardware_interface/EffortJointInterface</hardwareInterface>
      </joint>
      <actuator name="${fb}_${lr}_light_joint_motor">
        <hardwareInterface>EffortJointInterface</hardwareInterface>
        <mechanicalReduction>1</mechanicalReduction>
      </actuator>
    </transmission-->
  <!--fb : front, rear ; lr: left, right. type: trafficator, head, break, or rear-->
  <link name="rear_right_rear_light">
    <origin rpy="1.570796327 0 0" xyz="0 0 0"/>
    <visual>
      <material name="Turquoise"/>
      <geometry>
        <sphere radius="0.1"/>
      </geometry>
    </visual>
    <collision>
      <geometry>
        <sphere radius="0.1"/>
      </geometry>
    </collision>
    <origin rpy="0 0 0" xyz="0 0 0.029335"/>
    <inertial>
      <mass value="0.815"/>
      <inertia ixx="0.00326" ixy="0.0" ixz="0.0" iyy="0.00326" iyz="0.0" izz="0.00326"/>
    </inertial>
  </link>
  <joint name="rear_right_rear_light_joint" type="fixed">
    <parent link="rear_guard"/>
    <child link="rear_right_rear_light"/>
    <origin rpy="0 0 0" xyz="0.75 -0.9 0"/>
    <axis rpy="0 0 0" xyz="0 0 1"/>
    <limit effort="100" lower="0.0000" upper="0.0001" velocity="0"/>
    <!--joint_properties damping="10.0" friction="10.0"/-->
  </joint>
  <gazebo reference="rear_right_rear_light">
    <material>Gazebo/Turquoise</material>
  </gazebo>
  <!-- Transmission is important to link the joints and the controller -->
  <!--transmission name="${fb}_${lr}_{type}_light_joint_trans">
      <type>transmission_interface/SimpleTransmission</type>
      <joint name="${fb}_${lr}_${type}_light_joint" >
		<hardwareInterface>hardware_interface/EffortJointInterface</hardwareInterface>
      </joint>
      <actuator name="${fb}_${lr}_light_joint_motor">
        <hardwareInterface>EffortJointInterface</hardwareInterface>
        <mechanicalReduction>1</mechanicalReduction>
      </actuator>
    </transmission-->
  <!-- Lights  -->
  <!--fb : front, rear ; lr: left, right. type: trafficator, head, break, or rear-->
  <link name="rear_left_break_light">
    <origin rpy="1.570796327 0 0" xyz="0 0 0"/>
    <visual>
      <material name="Red"/>
      <geometry>
        <sphere radius="0.09"/>
      </geometry>
    </visual>
    <collision>
      <geometry>
        <sphere radius="0.09"/>
      </geometry>
    </collision>
    <origin rpy="0 0 0" xyz="0 0 0.029335"/>
    <inertial>
      <mass value="0.715"/>
      <inertia ixx="0.0023166" ixy="0.0" ixz="0.0" iyy="0.0023166" iyz="0.0" izz="0.0023166"/>
    </inertial>
  </link>
  <joint name="rear_left_break_light_joint" type="fixed">
    <parent link="rear_guard"/>
    <child link="rear_left_break_light"/>
    <origin rpy="0 0 0" xyz="0.7 0.7 0"/>
    <axis rpy="0 0 0" xyz="0 0 1"/>
    <limit effort="100" lower="0.0000" upper="0.0001" velocity="0"/>
    <!--joint_properties damping="10.0" friction="10.0"/-->
  </joint>
  <gazebo reference="rear_left_break_light">
    <material>Gazebo/Red</material>
  </gazebo>
  <!-- Transmission is important to link the joints and the controller -->
  <!--transmission name="${fb}_${lr}_{type}_light_joint_trans">
      <type>transmission_interface/SimpleTransmission</type>
      <joint name="${fb}_${lr}_${type}_light_joint" >
		<hardwareInterface>hardware_interface/EffortJointInterface</hardwareInterface>
      </joint>
      <actuator name="${fb}_${lr}_light_joint_motor">
        <hardwareInterface>EffortJointInterface</hardwareInterface>
        <mechanicalReduction>1</mechanicalReduction>
      </actuator>
    </transmission-->
  <!--fb : front, rear ; lr: left, right. type: trafficator, head, break, or rear-->
  <link name="rear_right_break_light">
    <origin rpy="1.570796327 0 0" xyz="0 0 0"/>
    <visual>
      <material name="Red"/>
      <geometry>
        <sphere radius="0.09"/>
      </geometry>
    </visual>
    <collision>
      <geometry>
        <sphere radius="0.09"/>
      </geometry>
    </collision>
    <origin rpy="0 0 0" xyz="0 0 0.029335"/>
    <inertial>
      <mass value="0.715"/>
      <inertia ixx="0.0023166" ixy="0.0" ixz="0.0" iyy="0.0023166" iyz="0.0" izz="0.0023166"/>
    </inertial>
  </link>
  <joint name="rear_right_break_light_joint" type="fixed">
    <parent link="rear_guard"/>
    <child link="rear_right_break_light"/>
    <origin rpy="0 0 0" xyz="0.7 -0.7 0"/>
    <axis rpy="0 0 0" xyz="0 0 1"/>
    <limit effort="100" lower="0.0000" upper="0.0001" velocity="0"/>
    <!--joint_properties damping="10.0" friction="10.0"/-->
  </joint>
  <gazebo reference="rear_right_break_light">
    <material>Gazebo/Red</material>
  </gazebo>
  <!-- Transmission is important to link the joints and the controller -->
  <!--transmission name="${fb}_${lr}_{type}_light_joint_trans">
      <type>transmission_interface/SimpleTransmission</type>
      <joint name="${fb}_${lr}_${type}_light_joint" >
		<hardwareInterface>hardware_interface/EffortJointInterface</hardwareInterface>
      </joint>
      <actuator name="${fb}_${lr}_light_joint_motor">
        <hardwareInterface>EffortJointInterface</hardwareInterface>
        <mechanicalReduction>1</mechanicalReduction>
      </actuator>
    </transmission-->
  <!--fb : front, rear ; lr: left, right. type: trafficator, head, break, or rear-->
  <link name="rear_left_reverse_light">
    <origin rpy="1.570796327 0 0" xyz="0 0 0"/>
    <visual>
      <material name="White"/>
      <geometry>
        <sphere radius="0.09"/>
      </geometry>
    </visual>
    <collision>
      <geometry>
        <sphere radius="0.09"/>
      </geometry>
    </collision>
    <origin rpy="0 0 0" xyz="0 0 0.029335"/>
    <inertial>
      <mass value="0.715"/>
      <inertia ixx="0.0023166" ixy="0.0" ixz="0.0" iyy="0.0023166" iyz="0.0" izz="0.0023166"/>
    </inertial>
  </link>
  <joint name="rear_left_reverse_light_joint" type="fixed">
    <parent link="rear_guard"/>
    <child link="rear_left_reverse_light"/>
    <origin rpy="0 0 0" xyz="0.9 0.7 0"/>
    <axis rpy="0 0 0" xyz="0 0 1"/>
    <limit effort="100" lower="0.0000" upper="0.0001" velocity="0"/>
    <!--joint_properties damping="10.0" friction="10.0"/-->
  </joint>
  <gazebo reference="rear_left_reverse_light">
    <material>Gazebo/White</material>
  </gazebo>
  <!-- Transmission is important to link the joints and the controller -->
  <!--transmission name="${fb}_${lr}_{type}_light_joint_trans">
      <type>transmission_interface/SimpleTransmission</type>
      <joint name="${fb}_${lr}_${type}_light_joint" >
		<hardwareInterface>hardware_interface/EffortJointInterface</hardwareInterface>
      </joint>
      <actuator name="${fb}_${lr}_light_joint_motor">
        <hardwareInterface>EffortJointInterface</hardwareInterface>
        <mechanicalReduction>1</mechanicalReduction>
      </actuator>
    </transmission-->
  <!--fb : front, rear ; lr: left, right. type: trafficator, head, break, or rear-->
  <link name="rear_right_reverse_light">
    <origin rpy="1.570796327 0 0" xyz="0 0 0"/>
    <visual>
      <material name="White"/>
      <geometry>
        <sphere radius="0.09"/>
      </geometry>
    </visual>
    <collision>
      <geometry>
        <sphere radius="0.09"/>
      </geometry>
    </collision>
    <origin rpy="0 0 0" xyz="0 0 0.029335"/>
    <inertial>
      <mass value="0.715"/>
      <inertia ixx="0.0023166" ixy="0.0" ixz="0.0" iyy="0.0023166" iyz="0.0" izz="0.0023166"/>
    </inertial>
  </link>
  <joint name="rear_right_reverse_light_joint" type="fixed">
    <parent link="rear_guard"/>
    <child link="rear_right_reverse_light"/>
    <origin rpy="0 0 0" xyz="0.9 -0.7 0"/>
    <axis rpy="0 0 0" xyz="0 0 1"/>
    <limit effort="100" lower="0.0000" upper="0.0001" velocity="0"/>
    <!--joint_properties damping="10.0" friction="10.0"/-->
  </joint>
  <gazebo reference="rear_right_reverse_light">
    <material>Gazebo/White</material>
  </gazebo>
  <!-- Transmission is important to link the joints and the controller -->
  <!--transmission name="${fb}_${lr}_{type}_light_joint_trans">
      <type>transmission_interface/SimpleTransmission</type>
      <joint name="${fb}_${lr}_${type}_light_joint" >
		<hardwareInterface>hardware_interface/EffortJointInterface</hardwareInterface>
      </joint>
      <actuator name="${fb}_${lr}_light_joint_motor">
        <hardwareInterface>EffortJointInterface</hardwareInterface>
        <mechanicalReduction>1</mechanicalReduction>
      </actuator>
    </transmission-->
  <!--fb : front, rear ; lr: left, right. type: trafficator, head, break, or rear-->
  <link name="rear_left_trafficator_light">
    <origin rpy="0 0 0" xyz="-0.58 -0.8 0"/>
    <visual>
      <material name="Orange"/>
      <geometry>
        <box size="0.08 0.04 0.056"/>
      </geometry>
    </visual>
    <collision>
      <geometry>
        <box size="0.08 0.04 0.056"/>
      </geometry>
    </collision>
    <origin rpy="0 0 0" xyz="0 0 0.029335"/>
    <inertial>
      <mass value="1.8"/>
      <inertia ixx="0.0012" ixy="0.0" ixz="0.0" iyy="0.0007104" iyz="0.0" izz="0.0014304"/>
    </inertial>
  </link>
  <gazebo reference="rear_left_trafficator_light">
    <material>Gazebo/Orange</material>
  </gazebo>
  <joint name="rear_left_trafficator_light_joint" type="fixed">
    <parent link="left_rear_chassis"/>
    <child link="rear_left_trafficator_light"/>
    <axis rpy="0 0 0" xyz="0 1 0"/>
    <limit effort="100" lower="0.0000" upper="0.0001" velocity="0"/>
    <origin rpy="0.0 0 0" xyz="-0.58 -0.8 0"/>
  </joint>
  <!-- Transmission is important to link the joints and the controller -->
  <!--transmission name="${fb}_${lr}_${type}_light_joint_trans">
      <type>transmission_interface/SimpleTransmission</type>
      <joint name="${fb}_${lr}_${type}_light_joint" >
		<hardwareInterface>hardware_interface/EffortJointInterface</hardwareInterface>
      </joint>
      <actuator name="${fb}_${lr}_${type}_light_joint_motor">
        <hardwareInterface>EffortJointInterface</hardwareInterface>
        <mechanicalReduction>1</mechanicalReduction>
      </actuator>
    </transmission-->
  <!--fb : front, rear ; lr: left, right. type: trafficator, head, break, or rear-->
  <link name="rear_right_trafficator_light">
    <origin rpy="0 0 0" xyz="-0.58 -0.8 0"/>
    <visual>
      <material name="Orange"/>
      <geometry>
        <box size="0.08 0.04 0.056"/>
      </geometry>
    </visual>
    <collision>
      <geometry>
        <box size="0.08 0.04 0.056"/>
      </geometry>
    </collision>
    <origin rpy="0 0 0" xyz="0 0 0.029335"/>
    <inertial>
      <mass value="1.8"/>
      <inertia ixx="0.0012" ixy="0.0" ixz="0.0" iyy="0.0007104" iyz="0.0" izz="0.0014304"/>
    </inertial>
  </link>
  <gazebo reference="rear_right_trafficator_light">
    <material>Gazebo/Orange</material>
  </gazebo>
  <joint name="rear_right_trafficator_light_joint" type="fixed">
    <parent link="right_rear_chassis"/>
    <child link="rear_right_trafficator_light"/>
    <axis rpy="0 0 0" xyz="0 1 0"/>
    <limit effort="100" lower="0.0000" upper="0.0001" velocity="0"/>
    <origin rpy="0.0 0 0" xyz="-0.58 -0.8 0"/>
  </joint>
  <!-- Transmission is important to link the joints and the controller -->
  <!--transmission name="${fb}_${lr}_${type}_light_joint_trans">
      <type>transmission_interface/SimpleTransmission</type>
      <joint name="${fb}_${lr}_${type}_light_joint" >
		<hardwareInterface>hardware_interface/EffortJointInterface</hardwareInterface>
      </joint>
      <actuator name="${fb}_${lr}_${type}_light_joint_motor">
        <hardwareInterface>EffortJointInterface</hardwareInterface>
        <mechanicalReduction>1</mechanicalReduction>
      </actuator>
    </transmission-->
  <!--fb : front, rear ; lr: left, right. type: trafficator, head, break, or rear-->
  <link name="rear_left_fog_light">
    <origin rpy="1.570796327 0 0" xyz="0 0 0"/>
    <visual>
      <material name="Yellow"/>
      <geometry>
        <sphere radius="0.056"/>
      </geometry>
    </visual>
    <collision>
      <geometry>
        <sphere radius="0.056"/>
      </geometry>
    </collision>
    <origin rpy="0 0 0" xyz="0 0 0.029335"/>
    <inertial>
      <mass value="0.052"/>
      <inertia ixx="6.52288e-05" ixy="0.0" ixz="0.0" iyy="6.52288e-05" iyz="0.0" izz="6.52288e-05"/>
    </inertial>
  </link>
  <joint name="rear_left_fog_light_joint" type="fixed">
    <parent link="rear_guard"/>
    <child link="rear_left_fog_light"/>
    <origin rpy="0 0 0" xyz="0.95 0.9 0"/>
    <axis rpy="0 0 0" xyz="0 0 1"/>
    <limit effort="100" lower="0.0000" upper="0.0001" velocity="0"/>
    <!--joint_properties damping="10.0" friction="10.0"/-->
  </joint>
  <gazebo reference="rear_left_fog_light">
    <material>Gazebo/Yellow</material>
  </gazebo>
  <!-- Transmission is important to link the joints and the controller -->
  <!--transmission name="${fb}_${lr}_{type}_light_joint_trans">
      <type>transmission_interface/SimpleTransmission</type>
      <joint name="${fb}_${lr}_${type}_light_joint" >
		<hardwareInterface>hardware_interface/EffortJointInterface</hardwareInterface>
      </joint>
      <actuator name="${fb}_${lr}_light_joint_motor">
        <hardwareInterface>EffortJointInterface</hardwareInterface>
        <mechanicalReduction>1</mechanicalReduction>
      </actuator>
    </transmission-->
  <!--fb : front, rear ; lr: left, right. type: trafficator, head, break, or rear-->
  <link name="rear_right_fog_light">
    <origin rpy="1.570796327 0 0" xyz="0 0 0"/>
    <visual>
      <material name="Yellow"/>
      <geometry>
        <sphere radius="0.056"/>
      </geometry>
    </visual>
    <collision>
      <geometry>
        <sphere radius="0.056"/>
      </geometry>
    </collision>
    <origin rpy="0 0 0" xyz="0 0 0.029335"/>
    <inertial>
      <mass value="1.8"/>
      <inertia ixx="0.00225792" ixy="0.0" ixz="0.0" iyy="0.00225792" iyz="0.0" izz="0.00225792"/>
    </inertial>
  </link>
  <joint name="rear_right_fog_light_joint" type="fixed">
    <parent link="rear_guard"/>
    <child link="rear_right_fog_light"/>
    <origin rpy="0 0 0" xyz="0.95 -0.9 0"/>
    <axis rpy="0 0 0" xyz="0 0 1"/>
    <limit effort="100" lower="0.0000" upper="0.0001" velocity="0"/>
    <!--joint_properties damping="10.0" friction="10.0"/-->
  </joint>
  <gazebo reference="rear_right_fog_light">
    <material>Gazebo/Yellow</material>
  </gazebo>
  <!-- Transmission is important to link the joints and the controller -->
  <!--transmission name="${fb}_${lr}_{type}_light_joint_trans">
      <type>transmission_interface/SimpleTransmission</type>
      <joint name="${fb}_${lr}_${type}_light_joint" >
		<hardwareInterface>hardware_interface/EffortJointInterface</hardwareInterface>
      </joint>
      <actuator name="${fb}_${lr}_light_joint_motor">
        <hardwareInterface>EffortJointInterface</hardwareInterface>
        <mechanicalReduction>1</mechanicalReduction>
      </actuator>
    </transmission-->
  <!-- bus engine. We used a 15cm .15m offset to the dashboard and front guard accessories  -->
  <link name="bus_engine">
    <visual>
      <!--origin xyz="${trX} ${trY} ${trZ}" rpy="${fX*M_PI} ${fY*M_PI} 0"/-->
      <geometry>
        <box size="0.3 1.95 0.36"/>
      </geometry>
    </visual>
    <collision>
      <!--origin xyz="${trX} ${trY} ${trZ}" rpy="${fX*M_PI} ${fY*M_PI} 0"/-->
      <geometry>
        <box size="0.3 1.95 0.36"/>
      </geometry>
    </collision>
    <origin rpy="0 0 0" xyz="0 0 0.029335"/>
    <inertial>
      <mass value="80.03"/>
      <inertia ixx="26.22383025" ixy="0.0" ixz="0.0" iyy="1.464549" iyz="0.0" izz="25.95973125"/>
    </inertial>
  </link>
  <gazebo reference="bus_engine">
    <material>Gazebo/BlueTransparent</material>
  </gazebo>
  <joint name="bus_engine_joint" type="prismatic">
    <parent link="base_link"/>
    <child link="bus_engine"/>
    <origin rpy="0.0 0.0 0" xyz="1.45 0 0.5101"/>
    <axis xyz="0 0 1"/>
    <limit effort="100" lower="0" upper="0.0001" velocity="0"/>
    <origin rpy="0.0 0.0 0" xyz="1.45 0 0.5101"/>
  </joint>
  <!-- Transmission is important to link the joints and the controller -->
  <transmission name="bus_engine_joint_trans">
    <type>transmission_interface/SimpleTransmission</type>
    <joint name="bus_engine_joint">
      <hardwareInterface>hardware_interface/EffortJointInterface</hardwareInterface>
    </joint>
    <actuator name="bus_engine_joint_motor">
      <hardwareInterface>EffortJointInterface</hardwareInterface>
      <mechanicalReduction>1</mechanicalReduction>
    </actuator>
  </transmission>
  <link name="break_anchor">
    <visual>
      <material name="DarkGrey"/>
      <geometry>
        <cylinder length="0.12" radius="0.03"/>
      </geometry>
      <material name="Black"/>
    </visual>
    <collision>
      <geometry>
        <cylinder length="0.12" radius="0.03"/>
      </geometry>
    </collision>
    <origin rpy="0 0 0" xyz="0 0 0.0029335"/>
    <inertial>
      <mass value="0.9"/>
      <inertia ixx="0.0012825" ixy="0.0" ixz="0.0" iyy="0.0012825" iyz="0.0" izz="0.001215"/>
    </inertial>
  </link>
  <!--gazebo reference="${type}_pedal">
      <material>Gazebo/DarkGrey</material>
    </gazebo-->
  <joint name="break_anchor_joint" type="prismatic">
    <parent link="bus_engine"/>
    <child link="break_anchor"/>
    <axis rpy="0 0 0" xyz="0 1 0"/>
    <origin rpy="0 -0.523598775667 0.0" xyz="-0.2 0.39 -0.072"/>
    <limit effort="100" lower="0" upper="0" velocity="10"/>
    <joint_properties damping="10.0" friction="100000.0"/>
  </joint>
  <!-- Transmission is important to link the joints and the controller -->
  <transmission name="break_anchor_joint_trans">
    <type>transmission_interface/SimpleTransmission</type>
    <joint name="break_anchor_joint">
      <hardwareInterface>hardware_interface/PositionJointInterface</hardwareInterface>
    </joint>
    <actuator name="break_anchor_joint_motor">
      <hardwareInterface>PositionJointInterface</hardwareInterface>
      <mechanicalReduction>1</mechanicalReduction>
    </actuator>
  </transmission>
  <link name="break_pedal">
    <origin rpy="0 -0.523598775667 0.0" xyz="-0.03 0 0.105"/>
    <visual>
      <material name="Red"/>
      <geometry>
        <box size="0.12 0.06 0.03"/>
      </geometry>
    </visual>
    <collision>
      <geometry>
        <box size="0.12 0.06 0.03"/>
      </geometry>
    </collision>
    <origin rpy="0 0 0" xyz="0 0 0.029335"/>
    <inertial>
      <mass value="0.9"/>
      <inertia ixx="0.0011475" ixy="0.0" ixz="0.0" iyy="0.0003375" iyz="0.0" izz="0.00135"/>
    </inertial>
  </link>
  <gazebo reference="break_pedal">
    <material>Gazebo/Red</material>
  </gazebo>
  <joint name="break_pedal_joint" type="prismatic">
    <parent link="break_anchor"/>
    <child link="break_pedal"/>
    <origin rpy="0 -0.523598775667 0.0" xyz="-0.03 0 0.105"/>
    <axis rpy="0 0 0" xyz="0 0 1"/>
    <calibration rising="0.01"/>
    <dynamics damping="0.0" friction="0.0"/>
    <limit effort="30" lower="0.01" upper="0.1" velocity="0.0"/>
    <safety_controller k_position="5" k_velocity="10" soft_lower_limit="-2.0" soft_upper_limit="0.5"/>
    <!--joint_properties damping="10.0" friction="2.0"/-->
  </joint>
  <!-- Transmission is important to link the joints and the controller -->
  <transmission name="break_pedal_joint_trans">
    <type>transmission_interface/SimpleTransmission</type>
    <joint name="break_pedal_joint">
      <hardwareInterface>hardware_interface/PositionJointInterface</hardwareInterface>
    </joint>
    <actuator name="break_pedal_joint_motor">
      <hardwareInterface>PositionJointInterface</hardwareInterface>
      <mechanicalReduction>1</mechanicalReduction>
    </actuator>
  </transmission>
  <link name="clutch_anchor">
    <visual>
      <material name="DarkGrey"/>
      <geometry>
        <cylinder length="0.12" radius="0.03"/>
      </geometry>
      <material name="Black"/>
    </visual>
    <collision>
      <geometry>
        <cylinder length="0.12" radius="0.03"/>
      </geometry>
    </collision>
    <origin rpy="0 0 0" xyz="0 0 0.0029335"/>
    <inertial>
      <mass value="0.9"/>
      <inertia ixx="0.0012825" ixy="0.0" ixz="0.0" iyy="0.0012825" iyz="0.0" izz="0.001215"/>
    </inertial>
  </link>
  <!--gazebo reference="${type}_pedal">
      <material>Gazebo/DarkGrey</material>
    </gazebo-->
  <joint name="clutch_anchor_joint" type="prismatic">
    <parent link="bus_engine"/>
    <child link="clutch_anchor"/>
    <axis rpy="0 0 0" xyz="0 1 0"/>
    <origin rpy="0 -0.523598775667 0.0" xyz="-0.2 0.312 -0.072"/>
    <limit effort="100" lower="0" upper="0" velocity="10"/>
    <joint_properties damping="10.0" friction="100000.0"/>
  </joint>
  <!-- Transmission is important to link the joints and the controller -->
  <transmission name="clutch_anchor_joint_trans">
    <type>transmission_interface/SimpleTransmission</type>
    <joint name="clutch_anchor_joint">
      <hardwareInterface>hardware_interface/PositionJointInterface</hardwareInterface>
    </joint>
    <actuator name="clutch_anchor_joint_motor">
      <hardwareInterface>PositionJointInterface</hardwareInterface>
      <mechanicalReduction>1</mechanicalReduction>
    </actuator>
  </transmission>
  <link name="clutch_pedal">
    <origin rpy="0 -0.523598775667 0.0" xyz="-0.03 0 0.105"/>
    <visual>
      <material name="BlueTransparent"/>
      <geometry>
        <box size="0.12 0.06 0.03"/>
      </geometry>
    </visual>
    <collision>
      <geometry>
        <box size="0.12 0.06 0.03"/>
      </geometry>
    </collision>
    <origin rpy="0 0 0" xyz="0 0 0.029335"/>
    <inertial>
      <mass value="0.9"/>
      <inertia ixx="0.0011475" ixy="0.0" ixz="0.0" iyy="0.0003375" iyz="0.0" izz="0.00135"/>
    </inertial>
  </link>
  <gazebo reference="clutch_pedal">
    <material>Gazebo/BlueTransparent</material>
  </gazebo>
  <joint name="clutch_pedal_joint" type="prismatic">
    <parent link="clutch_anchor"/>
    <child link="clutch_pedal"/>
    <origin rpy="0 -0.523598775667 0.0" xyz="-0.03 0 0.105"/>
    <axis rpy="0 0 0" xyz="0 0 1"/>
    <calibration rising="0.01"/>
    <dynamics damping="0.0" friction="0.0"/>
    <limit effort="30" lower="0.01" upper="0.1" velocity="0.0"/>
    <safety_controller k_position="5" k_velocity="10" soft_lower_limit="-2.0" soft_upper_limit="0.5"/>
    <!--joint_properties damping="10.0" friction="2.0"/-->
  </joint>
  <!-- Transmission is important to link the joints and the controller -->
  <transmission name="clutch_pedal_joint_trans">
    <type>transmission_interface/SimpleTransmission</type>
    <joint name="clutch_pedal_joint">
      <hardwareInterface>hardware_interface/PositionJointInterface</hardwareInterface>
    </joint>
    <actuator name="clutch_pedal_joint_motor">
      <hardwareInterface>PositionJointInterface</hardwareInterface>
      <mechanicalReduction>1</mechanicalReduction>
    </actuator>
  </transmission>
  <link name="accelerator_anchor">
    <visual>
      <material name="DarkGrey"/>
      <geometry>
        <cylinder length="0.12" radius="0.03"/>
      </geometry>
      <material name="Black"/>
    </visual>
    <collision>
      <geometry>
        <cylinder length="0.12" radius="0.03"/>
      </geometry>
    </collision>
    <origin rpy="0 0 0" xyz="0 0 0.0029335"/>
    <inertial>
      <mass value="0.9"/>
      <inertia ixx="0.0012825" ixy="0.0" ixz="0.0" iyy="0.0012825" iyz="0.0" izz="0.001215"/>
    </inertial>
  </link>
  <!--gazebo reference="${type}_pedal">
      <material>Gazebo/DarkGrey</material>
    </gazebo-->
  <joint name="accelerator_anchor_joint" type="prismatic">
    <parent link="bus_engine"/>
    <child link="accelerator_anchor"/>
    <axis rpy="0 0 0" xyz="0 1 0"/>
    <origin rpy="0 -0.523598775667 0.0" xyz="-0.2 0.234 -0.072"/>
    <limit effort="100" lower="0" upper="0" velocity="10"/>
    <joint_properties damping="10.0" friction="100000.0"/>
  </joint>
  <!-- Transmission is important to link the joints and the controller -->
  <transmission name="accelerator_anchor_joint_trans">
    <type>transmission_interface/SimpleTransmission</type>
    <joint name="accelerator_anchor_joint">
      <hardwareInterface>hardware_interface/PositionJointInterface</hardwareInterface>
    </joint>
    <actuator name="accelerator_anchor_joint_motor">
      <hardwareInterface>PositionJointInterface</hardwareInterface>
      <mechanicalReduction>1</mechanicalReduction>
    </actuator>
  </transmission>
  <link name="accelerator_pedal">
    <origin rpy="0 -0.523598775667 0.0" xyz="-0.03 0 0.105"/>
    <visual>
      <material name="DarkGrey"/>
      <geometry>
        <box size="0.12 0.06 0.03"/>
      </geometry>
    </visual>
    <collision>
      <geometry>
        <box size="0.12 0.06 0.03"/>
      </geometry>
    </collision>
    <origin rpy="0 0 0" xyz="0 0 0.029335"/>
    <inertial>
      <mass value="0.9"/>
      <inertia ixx="0.0011475" ixy="0.0" ixz="0.0" iyy="0.0003375" iyz="0.0" izz="0.00135"/>
    </inertial>
  </link>
  <gazebo reference="accelerator_pedal">
    <material>Gazebo/DarkGrey</material>
  </gazebo>
  <joint name="accelerator_pedal_joint" type="prismatic">
    <parent link="accelerator_anchor"/>
    <child link="accelerator_pedal"/>
    <origin rpy="0 -0.523598775667 0.0" xyz="-0.03 0 0.105"/>
    <axis rpy="0 0 0" xyz="0 0 1"/>
    <calibration rising="0.01"/>
    <dynamics damping="0.0" friction="0.0"/>
    <limit effort="30" lower="0.01" upper="0.1" velocity="0.0"/>
    <safety_controller k_position="5" k_velocity="10" soft_lower_limit="-2.0" soft_upper_limit="0.5"/>
    <!--joint_properties damping="10.0" friction="2.0"/-->
  </joint>
  <!-- Transmission is important to link the joints and the controller -->
  <transmission name="accelerator_pedal_joint_trans">
    <type>transmission_interface/SimpleTransmission</type>
    <joint name="accelerator_pedal_joint">
      <hardwareInterface>hardware_interface/PositionJointInterface</hardwareInterface>
    </joint>
    <actuator name="accelerator_pedal_joint_motor">
      <hardwareInterface>PositionJointInterface</hardwareInterface>
      <mechanicalReduction>1</mechanicalReduction>
    </actuator>
  </transmission>
  <link name="steering_anchor">
    <visual>
      <material name="DarkGrey"/>
      <geometry>
        <cylinder length="0.72" radius="0.03"/>
      </geometry>
      <material name="Black"/>
    </visual>
    <collision>
      <geometry>
        <cylinder length="0.72" radius="0.03"/>
      </geometry>
    </collision>
    <origin rpy="0 0 0" xyz="0 0 0.0029335"/>
    <inertial>
      <mass value="3.6"/>
      <inertia ixx="0.15633" ixy="0.0" ixz="0.0" iyy="0.15633" iyz="0.0" izz="0.00486"/>
    </inertial>
  </link>
  <!--gazebo reference="${type}_pedal">
      <material>Gazebo/DarkGrey</material>
    </gazebo-->
  <joint name="steering_anchor_joint" type="prismatic">
    <parent link="bus_engine"/>
    <child link="steering_anchor"/>
    <axis rpy="0 0 0" xyz="0 1 0"/>
    <origin rpy="0 -0.523598775667 0.0" xyz="-0.2 0.4875 0.18"/>
    <limit effort="100" lower="0" upper="0" velocity="10"/>
    <joint_properties damping="10.0" friction="100000.0"/>
  </joint>
  <!-- Transmission is important to link the joints and the controller -->
  <transmission name="steering_anchor_joint_trans">
    <type>transmission_interface/SimpleTransmission</type>
    <joint name="steering_anchor_joint">
      <hardwareInterface>hardware_interface/PositionJointInterface</hardwareInterface>
    </joint>
    <actuator name="steering_anchor_joint_motor">
      <hardwareInterface>PositionJointInterface</hardwareInterface>
      <mechanicalReduction>1</mechanicalReduction>
    </actuator>
  </transmission>
  <link name="steering_wheel">
    <visual>
      <material name="Green"/>
      <geometry>
        <cylinder length="0.015" radius="0.12"/>
      </geometry>
    </visual>
    <collision>
      <geometry>
        <cylinder length="0.015" radius="0.12"/>
      </geometry>
    </collision>
    <origin rpy="0 0 0" xyz="0 0 0.0029335"/>
    <inertial>
      <mass value="0.9"/>
      <inertia ixx="0.003256875" ixy="0.0" ixz="0.0" iyy="0.003256875" iyz="0.0" izz="0.01944"/>
    </inertial>
  </link>
  <link name="steering_wheel_camera_link">
    <origin rpy="0 0 0" xyz="0 0 0.029335"/>
    <inertial>
      <mass value="0.1"/>
      <inertia ixx="1.66666666667e-06" ixy="0.0" ixz="0.0" iyy="1.66666666667e-06" iyz="0.0" izz="1.66666666667e-06"/>
    </inertial>
    <collision>
      <origin rpy="0 0 0" xyz="0 0 0"/>
      <geometry>
        <box size="0.02 0.02 0.02"/>
      </geometry>
    </collision>
    <visual>
      <origin rpy="0 0 0" xyz="0 0 0"/>
      <geometry>
        <box size="0.02 0.02 0.02"/>
      </geometry>
      <material name="red"/>
    </visual>
    <origin rpy="0 0 0" xyz="0 0 0.029335"/>
    <inertial>
      <mass value="1e-06"/>
      <inertia ixx="6.66666666667e-11" ixy="0.0" ixz="0.0" iyy="6.66666666667e-11" iyz="0.0" izz="6.66666666667e-11"/>
    </inertial>
  </link>
  <joint name="steering_wheel_camera_joint" type="revolute">
    <parent link="steering_wheel"/>
    <child link="steering_wheel_camera_link"/>
    <origin rpy="0.0 -1.15610609667 0.0" xyz="0 0 0.04"/>
    <axis xyz="0 1 0"/>
    <limit effort="20" friction="20.0" lower="0" upper="0" velocity="0.11111"/>
  </joint>
  <transmission name="steering_wheel_camera_joint_trans">
    <type>transmission_interface/SimpleTransmission</type>
    <joint name="steering_wheel_camera_joint">
      <hardwareInterface>hardware_interface/EffortJointInterface</hardwareInterface>
    </joint>
    <actuator name="steering_wheel_camera_joint_motor">
      <hardwareInterface>EffortJointInterface</hardwareInterface>
      <mechanicalReduction>1</mechanicalReduction>
    </actuator>
  </transmission>
  <gazebo reference="steering_wheel_camera_link">
    <sensor name="steering_wheel_camera" type="camera">
      <update_rate>30.0</update_rate>
      <camera name="steering_wheel">
        <!--visualize>true</visualize-->
        <horizontal_fov>1.3962634</horizontal_fov>
        <image>
          <width>800</width>
          <height>800</height>
          <format>R8G8B8</format>
        </image>
        <clip>
          <near>0.02</near>
          <far>300</far>
        </clip>
        <noise>
          <type>gaussian</type>
          <!-- Noise is sampled independently per pixel on each frame.
               That pixel's noise value is added to each of its color
               channels, which at that point lie in the range [0,1]. -->
          <mean>0.0</mean>
          <stddev>0.007</stddev>
        </noise>
      </camera>
      <plugin filename="libgazebo_ros_camera.so" name="camera_controller">
        <material>Gazebo/Gold</material>
        <alwaysOn>true</alwaysOn>
        <updateRate>30.0</updateRate>
        <visualize>true</visualize>
        <cameraName>steering_wheel_camera</cameraName>
        <imageTopicName>image_raw</imageTopicName>
        <cameraInfoTopicName>camera_info</cameraInfoTopicName>
        <frameName>steering_wheel_camera_link</frameName>
        <robotNamespace>/navya_bus</robotNamespace>
        <hackBaseline>0.07</hackBaseline>
        <distortionK1>0.0</distortionK1>
        <distortionK2>0.0</distortionK2>
        <distortionK3>0.0</distortionK3>
        <distortionT1>0.0</distortionT1>
        <distortionT2>0.0</distortionT2>
      </plugin>
    </sensor>
  </gazebo>
  <gazebo reference="steering_wheel">
    <material>Gazebo/Green</material>
  </gazebo>
  <joint name="steering_wheel_joint" type="revolute">
    <parent link="steering_anchor"/>
    <child link="steering_wheel"/>
    <origin rpy="0 -0.523598775667 0" xyz="-0.007 0 0.3925"/>
    <axis rpy="0 0 0.0174546887856" xyz="0 0 1"/>
    <limit effort="100.00" lower="-6.283185308" upper="6.283185308" velocity="0.01"/>
    <joint_properties damping="10.0" friction="0.0"/>
  </joint>
  <!-- Transmission is important to link the joints and the controller -->
  <transmission name="steering_wheel_joint_trans">
    <type>transmission_interface/SimpleTransmission</type>
    <joint name="steering_wheel_joint">
      <hardwareInterface>hardware_interface/EffortJointInterface</hardwareInterface>
    </joint>
    <actuator name="steering_wheel_joint_motor">
      <hardwareInterface>EffortJointInterface</hardwareInterface>
      <mechanicalReduction>1</mechanicalReduction>
    </actuator>
  </transmission>
  <!--bh : bonnet, hood-->
  <link name="bonnet">
    <origin rpy="0 -1.570796327 0" xyz="-0.315  0 -0.3"/>
    <material name="Purple"/>
    <visual>
      <origin rpy="0 0 0" xyz="0.1575 0 0"/>
      <geometry>
        <box size="0.3 1.95 0.045"/>
      </geometry>
    </visual>
    <collision>
      <origin rpy="0 0 0" xyz="0.1575 0 0"/>
      <geometry>
        <box size="0.3 1.95 0.045"/>
      </geometry>
    </collision>
    <origin rpy="0 0 0" xyz="0 0 0.029335"/>
    <inertial>
      <mass value="8.003"/>
      <inertia ixx="2.53730113125" ixy="0.0" ixz="0.0" iyy="0.06137300625" iyz="0.0" izz="2.595973125"/>
    </inertial>
  </link>
  <gazebo reference="bonnet">
    <material>Gazebo/Purple</material>
  </gazebo>
  <joint name="bonnet_joint" type="revolute">
    <parent link="front_guard"/>
    <child link="bonnet"/>
    <origin rpy="0 -1.570796327 0" xyz="-0.315  0 -0.3"/>
    <axis rpy="0 1 0" xyz="0 1 0"/>
    <limit effort="100" lower="-1.570796327" upper="0.7853" velocity="0"/>
    <joint_properties damping="1000.0" friction="100.0"/>
  </joint>
  <!-- Transmission is important to link the joints and the controller -->
  <transmission name="bonnet_joint_trans">
    <type>transmission_interface/SimpleTransmission</type>
    <joint name="bonnet_joint">
      <hardwareInterface>hardware_interface/EffortJointInterface</hardwareInterface>
    </joint>
    <actuator name="bonnet_joint_motor">
      <hardwareInterface>EffortJointInterface</hardwareInterface>
      <mechanicalReduction>1</mechanicalReduction>
    </actuator>
  </transmission>
  <!--fr : front,rear-->
  <link name="left_engine_cover_chassis">
    <visual>
      <material name="Black"/>
      <origin rpy="0 0 0" xyz="0 0 0"/>
      <geometry>
        <box size="0.3 0.63 0.05"/>
      </geometry>
    </visual>
    <collision>
      <origin rpy="0 0 0" xyz="0 0 0"/>
      <geometry>
        <box size="0.3 0.63 0.05"/>
      </geometry>
    </collision>
    <origin rpy="0 0 0" xyz="0 0 0.029335"/>
    <inertial>
      <mass value="6.0"/>
      <inertia ixx="0.1997" ixy="0.0" ixz="0.0" iyy="0.04625" iyz="0.0" izz="0.24345"/>
    </inertial>
  </link>
  <gazebo reference="left_engine_cover_chassis">
    <material>Gazebo/Black</material>
  </gazebo>
  <joint name="left_engine_cover_chassis_joint" type="fixed">
    <parent link="base_link"/>
    <child link="left_engine_cover_chassis"/>
    <origin rpy="1.570796327 0.0  0" xyz="1.55 1.025 0.6451"/>
    <limit effort="100.0" friction="120" lower="0" upper="0.0000104719755" velocity="0.01"/>
  </joint>
  <!--transmission name="${lr}_${fb}_chassis_joint_trans">
      <type>transmission_interface/SimpleTransmission</type>
      <joint name="${lr}_${fb}_chassis_joint" >
      <hardwareInterface>hardware_interface/EffortJointInterface</hardwareInterface>
      </joint>
      <actuator name="${lr}_${fb}_chassis_joint_motor">
		  <hardwareInterface>EffortJointInterface</hardwareInterface>
        <mechanicalReduction>1</mechanicalReduction>
      </actuator>
    </transmission-->
  <!--fr : front,rear-->
  <link name="right_engine_cover_chassis">
    <visual>
      <material name="Black"/>
      <origin rpy="0 0 0" xyz="0 0 0"/>
      <geometry>
        <box size="0.3 0.63 0.05"/>
      </geometry>
    </visual>
    <collision>
      <origin rpy="0 0 0" xyz="0 0 0"/>
      <geometry>
        <box size="0.3 0.63 0.05"/>
      </geometry>
    </collision>
    <origin rpy="0 0 0" xyz="0 0 0.029335"/>
    <inertial>
      <mass value="6.0"/>
      <inertia ixx="0.1997" ixy="0.0" ixz="0.0" iyy="0.04625" iyz="0.0" izz="0.24345"/>
    </inertial>
  </link>
  <gazebo reference="right_engine_cover_chassis">
    <material>Gazebo/Black</material>
  </gazebo>
  <joint name="right_engine_cover_chassis_joint" type="fixed">
    <parent link="base_link"/>
    <child link="right_engine_cover_chassis"/>
    <origin rpy="1.570796327 0.0  0" xyz="1.55 -1.025 0.6451"/>
    <limit effort="100.0" friction="120" lower="0" upper="0.0000104719755" velocity="0.01"/>
  </joint>
  <!--transmission name="${lr}_${fb}_chassis_joint_trans">
      <type>transmission_interface/SimpleTransmission</type>
      <joint name="${lr}_${fb}_chassis_joint" >
      <hardwareInterface>hardware_interface/EffortJointInterface</hardwareInterface>
      </joint>
      <actuator name="${lr}_${fb}_chassis_joint_motor">
		  <hardwareInterface>EffortJointInterface</hardwareInterface>
        <mechanicalReduction>1</mechanicalReduction>
      </actuator>
    </transmission-->
  <!--fr : front,rear-->
  <link name="left_front_chassis">
    <visual>
      <material name="DarkGrey"/>
      <origin rpy="0 0 0" xyz="0 0 0"/>
      <geometry>
        <box size="1.02 2.1 0.05"/>
      </geometry>
    </visual>
    <collision>
      <origin rpy="0 0 0" xyz="0 0 0"/>
      <geometry>
        <box size="1.02 2.1 0.05"/>
      </geometry>
    </collision>
    <origin rpy="0 0 0" xyz="0 0 0.029335"/>
    <inertial>
      <mass value="30.0"/>
      <inertia ixx="11.03125" ixy="0.0" ixz="0.0" iyy="2.60725" iyz="0.0" izz="13.626"/>
    </inertial>
  </link>
  <gazebo reference="left_front_chassis">
    <material>Gazebo/DarkGrey</material>
  </gazebo>
  <joint name="left_front_chassis_joint" type="fixed">
    <parent link="base_link"/>
    <child link="left_front_chassis"/>
    <origin rpy="1.570796327 0.0  0" xyz="0.85 1.025 1.3801"/>
    <limit effort="100.0" friction="120" lower="0" upper="0.0000104719755" velocity="0.01"/>
  </joint>
  <!--transmission name="${lr}_${fb}_chassis_joint_trans">
      <type>transmission_interface/SimpleTransmission</type>
      <joint name="${lr}_${fb}_chassis_joint" >
      <hardwareInterface>hardware_interface/EffortJointInterface</hardwareInterface>
      </joint>
      <actuator name="${lr}_${fb}_chassis_joint_motor">
		  <hardwareInterface>EffortJointInterface</hardwareInterface>
        <mechanicalReduction>1</mechanicalReduction>
      </actuator>
    </transmission-->
  <!--fr : front,rear-->
  <link name="right_front_chassis">
    <visual>
      <material name="DarkGrey"/>
      <origin rpy="0 0 0" xyz="0 0 0"/>
      <geometry>
        <box size="1.02 2.1 0.05"/>
      </geometry>
    </visual>
    <collision>
      <origin rpy="0 0 0" xyz="0 0 0"/>
      <geometry>
        <box size="1.02 2.1 0.05"/>
      </geometry>
    </collision>
    <origin rpy="0 0 0" xyz="0 0 0.029335"/>
    <inertial>
      <mass value="30.0"/>
      <inertia ixx="11.03125" ixy="0.0" ixz="0.0" iyy="2.60725" iyz="0.0" izz="13.626"/>
    </inertial>
  </link>
  <gazebo reference="right_front_chassis">
    <material>Gazebo/DarkGrey</material>
  </gazebo>
  <joint name="right_front_chassis_joint" type="fixed">
    <parent link="base_link"/>
    <child link="right_front_chassis"/>
    <origin rpy="1.570796327 0.0  0" xyz="0.85 -1.025 1.3801"/>
    <limit effort="100.0" friction="120" lower="0" upper="0.0000104719755" velocity="0.01"/>
  </joint>
  <!--transmission name="${lr}_${fb}_chassis_joint_trans">
      <type>transmission_interface/SimpleTransmission</type>
      <joint name="${lr}_${fb}_chassis_joint" >
      <hardwareInterface>hardware_interface/EffortJointInterface</hardwareInterface>
      </joint>
      <actuator name="${lr}_${fb}_chassis_joint_motor">
		  <hardwareInterface>EffortJointInterface</hardwareInterface>
        <mechanicalReduction>1</mechanicalReduction>
      </actuator>
    </transmission-->
  <link name="front_windscreen">
    <visual>
      <transparency>1.00</transparency>
      <geometry>
        <box size="1.51958 2.1 0.025"/>
      </geometry>
    </visual>
    <collision>
      <geometry>
        <box size="1.51958 2.1 0.025"/>
      </geometry>
    </collision>
    <origin rpy="0 0 0" xyz="0 0 0.029335"/>
    <inertial>
      <mass value="12.0"/>
      <inertia ixx="4.410625" ixy="0.0" ixz="0.0" iyy="2.3097483764" iyz="0.0" izz="6.7191233764"/>
    </inertial>
  </link>
  <link name="front_windscreen_camera_link">
    <origin rpy="0 0 0" xyz="0 0 0.029335"/>
    <inertial>
      <mass value="0.1"/>
      <inertia ixx="1.66666666667e-06" ixy="0.0" ixz="0.0" iyy="1.66666666667e-06" iyz="0.0" izz="1.66666666667e-06"/>
    </inertial>
    <collision>
      <origin rpy="0 0 0" xyz="0 0 0"/>
      <geometry>
        <box size="0.02 0.02 0.02"/>
      </geometry>
    </collision>
    <visual>
      <origin rpy="0 0 0" xyz="0 0 0"/>
      <geometry>
        <box size="0.02 0.02 0.02"/>
      </geometry>
      <material name="red"/>
    </visual>
    <origin rpy="0 0 0" xyz="0 0 0.029335"/>
    <inertial>
      <mass value="1e-06"/>
      <inertia ixx="6.66666666667e-11" ixy="0.0" ixz="0.0" iyy="6.66666666667e-11" iyz="0.0" izz="6.66666666667e-11"/>
    </inertial>
  </link>
  <joint name="front_windscreen_camera_joint" type="revolute">
    <parent link="front_windscreen"/>
    <child link="front_windscreen_camera_link"/>
    <origin rpy="0.0 -1.2566370616 0.0" xyz="-0.05 0 0"/>
    <axis xyz="0 0 1"/>
    <limit effort="20" friction="20.0" lower="0" upper="0" velocity="0.11111"/>
  </joint>
  <transmission name="front_windscreen_camera_joint_trans">
    <type>transmission_interface/SimpleTransmission</type>
    <joint name="front_windscreen_camera_joint">
      <hardwareInterface>hardware_interface/EffortJointInterface</hardwareInterface>
    </joint>
    <actuator name="front_windscreen_camera_joint_motor">
      <hardwareInterface>EffortJointInterface</hardwareInterface>
      <mechanicalReduction>1</mechanicalReduction>
    </actuator>
  </transmission>
  <gazebo reference="front_windscreen_camera_link">
    <sensor name="front_windscreen_camera" type="camera">
      <update_rate>30.0</update_rate>
      <camera name="front_windscreen">
        <!--visualize>true</visualize-->
        <horizontal_fov>1.3962634</horizontal_fov>
        <image>
          <width>800</width>
          <height>800</height>
          <format>R8G8B8</format>
        </image>
        <clip>
          <near>0.02</near>
          <far>300</far>
        </clip>
        <noise>
          <type>gaussian</type>
          <!-- Noise is sampled independently per pixel on each frame.
               That pixel's noise value is added to each of its color
               channels, which at that point lie in the range [0,1]. -->
          <mean>0.0</mean>
          <stddev>0.007</stddev>
        </noise>
      </camera>
      <plugin filename="libgazebo_ros_camera.so" name="camera_controller">
        <material>Gazebo/Gold</material>
        <alwaysOn>true</alwaysOn>
        <updateRate>30.0</updateRate>
        <visualize>true</visualize>
        <cameraName>front_windscreen_camera</cameraName>
        <imageTopicName>image_raw</imageTopicName>
        <cameraInfoTopicName>camera_info</cameraInfoTopicName>
        <frameName>front_windscreen_camera_link</frameName>
        <robotNamespace>/navya_bus</robotNamespace>
        <hackBaseline>0.07</hackBaseline>
        <distortionK1>0.0</distortionK1>
        <distortionK2>0.0</distortionK2>
        <distortionK3>0.0</distortionK3>
        <distortionT1>0.0</distortionT1>
        <distortionT2>0.0</distortionT2>
      </plugin>
    </sensor>
  </gazebo>
  <gazebo reference="front_windscreen">
    <material>Gazebo/GreenTransparent</material>
  </gazebo>
  <joint name="front_windscreen_joint" type="prismatic">
    <parent link="roof_chassis"/>
    <child link="front_windscreen"/>
    <limit effort="20" friction="2000" lower="0" upper="0" velocity="0.001"/>
    <axis xyz="1 0 0"/>
    <origin rpy=" 0.0 1.54999898363 0.0" xyz="1.365 0 -0.75979"/>
  </joint>
  <transmission name="front_windscreen_trans">
    <type>transmission_interface/SimpleTransmission</type>
    <joint name="front_windscreen_joint">
      <hardwareInterface>hardware_interface/EffortJointInterface</hardwareInterface>
    </joint>
    <actuator name="front_windscreen_joint_motor">
      <hardwareInterface>EffortJointInterface</hardwareInterface>
      <mechanicalReduction>1</mechanicalReduction>
    </actuator>
  </transmission>
  <link name="rear_windscreen">
    <visual>
      <transparency>1.00</transparency>
      <geometry>
        <box size="1.02 2.1 0.025"/>
      </geometry>
    </visual>
    <collision>
      <geometry>
        <box size="1.02 2.1 0.025"/>
      </geometry>
    </collision>
    <origin rpy="0 0 0" xyz="0 0 0.029335"/>
    <inertial>
      <mass value="12.0"/>
      <inertia ixx="4.410625" ixy="0.0" ixz="0.0" iyy="1.041025" iyz="0.0" izz="5.4504"/>
    </inertial>
  </link>
  <link name="rear_windscreen_camera_link">
    <origin rpy="0 0 0" xyz="0 0 0.029335"/>
    <inertial>
      <mass value="0.1"/>
      <inertia ixx="1.66666666667e-06" ixy="0.0" ixz="0.0" iyy="1.66666666667e-06" iyz="0.0" izz="1.66666666667e-06"/>
    </inertial>
    <collision>
      <origin rpy="0 0 0" xyz="0 0 0"/>
      <geometry>
        <box size="0.02 0.02 0.02"/>
      </geometry>
    </collision>
    <visual>
      <origin rpy="0 0 0" xyz="0 0 0"/>
      <geometry>
        <box size="0.02 0.02 0.02"/>
      </geometry>
      <material name="red"/>
    </visual>
    <origin rpy="0 0 0" xyz="0 0 0.029335"/>
    <inertial>
      <mass value="1e-06"/>
      <inertia ixx="6.66666666667e-11" ixy="0.0" ixz="0.0" iyy="6.66666666667e-11" iyz="0.0" izz="6.66666666667e-11"/>
    </inertial>
  </link>
  <joint name="rear_windscreen_camera_joint" type="revolute">
    <parent link="rear_windscreen"/>
    <child link="rear_windscreen_camera_link"/>
    <origin rpy="3.141592654 -2.0420352251 0.0" xyz="-0.05 0 0"/>
    <axis xyz="0 0 1"/>
    <limit effort="20" friction="20.0" lower="0" upper="0" velocity="0.11111"/>
  </joint>
  <transmission name="rear_windscreen_camera_joint_trans">
    <type>transmission_interface/SimpleTransmission</type>
    <joint name="rear_windscreen_camera_joint">
      <hardwareInterface>hardware_interface/EffortJointInterface</hardwareInterface>
    </joint>
    <actuator name="rear_windscreen_camera_joint_motor">
      <hardwareInterface>EffortJointInterface</hardwareInterface>
      <mechanicalReduction>1</mechanicalReduction>
    </actuator>
  </transmission>
  <gazebo reference="rear_windscreen_camera_link">
    <sensor name="rear_windscreen_camera" type="camera">
      <update_rate>30.0</update_rate>
      <camera name="rear_windscreen">
        <!--visualize>true</visualize-->
        <horizontal_fov>1.3962634</horizontal_fov>
        <image>
          <width>800</width>
          <height>800</height>
          <format>R8G8B8</format>
        </image>
        <clip>
          <near>0.02</near>
          <far>300</far>
        </clip>
        <noise>
          <type>gaussian</type>
          <!-- Noise is sampled independently per pixel on each frame.
               That pixel's noise value is added to each of its color
               channels, which at that point lie in the range [0,1]. -->
          <mean>0.0</mean>
          <stddev>0.007</stddev>
        </noise>
      </camera>
      <plugin filename="libgazebo_ros_camera.so" name="camera_controller">
        <material>Gazebo/Gold</material>
        <alwaysOn>true</alwaysOn>
        <updateRate>30.0</updateRate>
        <visualize>true</visualize>
        <cameraName>rear_windscreen_camera</cameraName>
        <imageTopicName>image_raw</imageTopicName>
        <cameraInfoTopicName>camera_info</cameraInfoTopicName>
        <frameName>rear_windscreen_camera_link</frameName>
        <robotNamespace>/navya_bus</robotNamespace>
        <hackBaseline>0.07</hackBaseline>
        <distortionK1>0.0</distortionK1>
        <distortionK2>0.0</distortionK2>
        <distortionK3>0.0</distortionK3>
        <distortionT1>0.0</distortionT1>
        <distortionT2>0.0</distortionT2>
      </plugin>
    </sensor>
  </gazebo>
  <gazebo reference="rear_windscreen">
    <material>Gazebo/GreenTransparent</material>
  </gazebo>
  <joint name="rear_windscreen_joint" type="prismatic">
    <parent link="roof_chassis"/>
    <child link="rear_windscreen"/>
    <limit effort="20" friction="2000" lower="0" upper="0" velocity="0.001"/>
    <axis xyz="1 0 0"/>
    <origin rpy=" 0.0 -1.27079621969 0.0" xyz="-1.55 0 -0.51"/>
  </joint>
  <transmission name="rear_windscreen_trans">
    <type>transmission_interface/SimpleTransmission</type>
    <joint name="rear_windscreen_joint">
      <hardwareInterface>hardware_interface/EffortJointInterface</hardwareInterface>
    </joint>
    <actuator name="rear_windscreen_joint_motor">
      <hardwareInterface>EffortJointInterface</hardwareInterface>
      <mechanicalReduction>1</mechanicalReduction>
    </actuator>
  </transmission>
  <link name="left_door_anchor">
    <visual>
      <material name="Red"/>
      <origin rpy="0 0 0" xyz="0 0 0"/>
      <geometry>
        <box size="0.7 0.2 0.05"/>
      </geometry>
    </visual>
    <collision>
      <origin rpy="0 0 0" xyz="0 0 0"/>
      <geometry>
        <box size="0.7 0.2 0.05"/>
      </geometry>
    </collision>
    <origin rpy="0 0 0" xyz="0 0 0.029335"/>
    <inertial>
      <mass value="20.67"/>
      <inertia ixx="0.07320625" ixy="0.0" ixz="0.0" iyy="0.84833125" iyz="0.0" izz="0.912925"/>
    </inertial>
  </link>
  <gazebo reference="left_door_anchor">
    <material>Gazebo/Purple</material>
  </gazebo>
  <link name="left_door_anchor_camera_link">
    <origin rpy="0 0 0" xyz="0 0 0.029335"/>
    <inertial>
      <mass value="0.1"/>
      <inertia ixx="1.66666666667e-06" ixy="0.0" ixz="0.0" iyy="1.66666666667e-06" iyz="0.0" izz="1.66666666667e-06"/>
    </inertial>
    <collision>
      <origin rpy="0 0 0" xyz="0 0 0"/>
      <geometry>
        <box size="0.02 0.02 0.02"/>
      </geometry>
    </collision>
    <visual>
      <origin rpy="0 0 0" xyz="0 0 0"/>
      <geometry>
        <box size="0.02 0.02 0.02"/>
      </geometry>
      <material name="red"/>
    </visual>
    <origin rpy="0 0 0" xyz="0 0 0.029335"/>
    <inertial>
      <mass value="1e-06"/>
      <inertia ixx="6.66666666667e-11" ixy="0.0" ixz="0.0" iyy="6.66666666667e-11" iyz="0.0" izz="6.66666666667e-11"/>
    </inertial>
  </link>
  <joint name="left_door_anchor_camera_joint" type="revolute">
    <parent link="left_door_anchor"/>
    <child link="left_door_anchor_camera_link"/>
    <origin rpy="0.0 0.0 1.570796327" xyz="0 0 0.07"/>
    <axis xyz="1 0 0"/>
    <limit effort="20" friction="20.0" lower="0" upper="0" velocity="0.11111"/>
  </joint>
  <transmission name="left_door_anchor_camera_joint_trans">
    <type>transmission_interface/SimpleTransmission</type>
    <joint name="left_door_anchor_camera_joint">
      <hardwareInterface>hardware_interface/EffortJointInterface</hardwareInterface>
    </joint>
    <actuator name="left_door_anchor_camera_joint_motor">
      <hardwareInterface>EffortJointInterface</hardwareInterface>
      <mechanicalReduction>1</mechanicalReduction>
    </actuator>
  </transmission>
  <gazebo reference="left_door_anchor_camera_link">
    <sensor name="left_door_anchor_camera" type="camera">
      <update_rate>30.0</update_rate>
      <camera name="left_door_anchor">
        <!--visualize>true</visualize-->
        <horizontal_fov>1.3962634</horizontal_fov>
        <image>
          <width>800</width>
          <height>800</height>
          <format>R8G8B8</format>
        </image>
        <clip>
          <near>0.02</near>
          <far>300</far>
        </clip>
        <noise>
          <type>gaussian</type>
          <!-- Noise is sampled independently per pixel on each frame.
               That pixel's noise value is added to each of its color
               channels, which at that point lie in the range [0,1]. -->
          <mean>0.0</mean>
          <stddev>0.007</stddev>
        </noise>
      </camera>
      <plugin filename="libgazebo_ros_camera.so" name="camera_controller">
        <material>Gazebo/Gold</material>
        <alwaysOn>true</alwaysOn>
        <updateRate>30.0</updateRate>
        <visualize>true</visualize>
        <cameraName>left_door_anchor_camera</cameraName>
        <imageTopicName>image_raw</imageTopicName>
        <cameraInfoTopicName>camera_info</cameraInfoTopicName>
        <frameName>left_door_anchor_camera_link</frameName>
        <robotNamespace>/navya_bus</robotNamespace>
        <hackBaseline>0.07</hackBaseline>
        <distortionK1>0.0</distortionK1>
        <distortionK2>0.0</distortionK2>
        <distortionK3>0.0</distortionK3>
        <distortionT1>0.0</distortionT1>
        <distortionT2>0.0</distortionT2>
      </plugin>
    </sensor>
  </gazebo>
  <!--xacro:my_camera parent="${lr}_door" pos="${lr}_door"
   rX="1" rY="0" rZ="0" tX="0" tY="${-0.05}" tZ="0"
   fX="${rcX}" fY="${rcY}" fZ="${rcZ}"/-->
  <joint name="left_door_anchor_joint" type="prismatic">
    <parent link="base_link"/>
    <child link="left_door_anchor"/>
    <axis xyz="-1 0 0"/>
    <!-- door opens by itself so closing it here -->
    <!--limit effort="0" velocity="0.0" friction="100.0" lower="0" upper="${l}"/-->
    <limit effort="10000" friction="1000.0" lower="0" upper="0" velocity=".50"/>
    <origin rpy="0.0 0.0 0.0" xyz="-0.01 1.025 0.3301"/>
    <!--origin xyz="0 0 0" rpy="0 0 0" /-->
  </joint>
  <transmission name="left_door_anchor_joint_trans">
    <type>transmission_interface/SimpleTransmission</type>
    <joint name="left_door_anchor_joint">
      <hardwareInterface>hardware_interface/EffortJointInterface</hardwareInterface>
    </joint>
    <actuator name="left_door_anchor_joint_motor">
      <hardwareInterface>EffortJointInterface</hardwareInterface>
      <mechanicalReduction>1</mechanicalReduction>
    </actuator>
  </transmission>
  <link name="right_door_anchor">
    <visual>
      <material name="Red"/>
      <origin rpy="0 0 0" xyz="0 0 0"/>
      <geometry>
        <box size="0.7 0.2 0.05"/>
      </geometry>
    </visual>
    <collision>
      <origin rpy="0 0 0" xyz="0 0 0"/>
      <geometry>
        <box size="0.7 0.2 0.05"/>
      </geometry>
    </collision>
    <origin rpy="0 0 0" xyz="0 0 0.029335"/>
    <inertial>
      <mass value="20.67"/>
      <inertia ixx="0.07320625" ixy="0.0" ixz="0.0" iyy="0.84833125" iyz="0.0" izz="0.912925"/>
    </inertial>
  </link>
  <gazebo reference="right_door_anchor">
    <material>Gazebo/Purple</material>
  </gazebo>
  <link name="right_door_anchor_camera_link">
    <origin rpy="0 0 0" xyz="0 0 0.029335"/>
    <inertial>
      <mass value="0.1"/>
      <inertia ixx="1.66666666667e-06" ixy="0.0" ixz="0.0" iyy="1.66666666667e-06" iyz="0.0" izz="1.66666666667e-06"/>
    </inertial>
    <collision>
      <origin rpy="0 0 0" xyz="0 0 0"/>
      <geometry>
        <box size="0.02 0.02 0.02"/>
      </geometry>
    </collision>
    <visual>
      <origin rpy="0 0 0" xyz="0 0 0"/>
      <geometry>
        <box size="0.02 0.02 0.02"/>
      </geometry>
      <material name="red"/>
    </visual>
    <origin rpy="0 0 0" xyz="0 0 0.029335"/>
    <inertial>
      <mass value="1e-06"/>
      <inertia ixx="6.66666666667e-11" ixy="0.0" ixz="0.0" iyy="6.66666666667e-11" iyz="0.0" izz="6.66666666667e-11"/>
    </inertial>
  </link>
  <joint name="right_door_anchor_camera_joint" type="revolute">
    <parent link="right_door_anchor"/>
    <child link="right_door_anchor_camera_link"/>
    <origin rpy="0.0 0.0 -1.570796327" xyz="0 0 0.07"/>
    <axis xyz="1 0 0"/>
    <limit effort="20" friction="20.0" lower="0" upper="0" velocity="0.11111"/>
  </joint>
  <transmission name="right_door_anchor_camera_joint_trans">
    <type>transmission_interface/SimpleTransmission</type>
    <joint name="right_door_anchor_camera_joint">
      <hardwareInterface>hardware_interface/EffortJointInterface</hardwareInterface>
    </joint>
    <actuator name="right_door_anchor_camera_joint_motor">
      <hardwareInterface>EffortJointInterface</hardwareInterface>
      <mechanicalReduction>1</mechanicalReduction>
    </actuator>
  </transmission>
  <gazebo reference="right_door_anchor_camera_link">
    <sensor name="right_door_anchor_camera" type="camera">
      <update_rate>30.0</update_rate>
      <camera name="right_door_anchor">
        <!--visualize>true</visualize-->
        <horizontal_fov>1.3962634</horizontal_fov>
        <image>
          <width>800</width>
          <height>800</height>
          <format>R8G8B8</format>
        </image>
        <clip>
          <near>0.02</near>
          <far>300</far>
        </clip>
        <noise>
          <type>gaussian</type>
          <!-- Noise is sampled independently per pixel on each frame.
               That pixel's noise value is added to each of its color
               channels, which at that point lie in the range [0,1]. -->
          <mean>0.0</mean>
          <stddev>0.007</stddev>
        </noise>
      </camera>
      <plugin filename="libgazebo_ros_camera.so" name="camera_controller">
        <material>Gazebo/Gold</material>
        <alwaysOn>true</alwaysOn>
        <updateRate>30.0</updateRate>
        <visualize>true</visualize>
        <cameraName>right_door_anchor_camera</cameraName>
        <imageTopicName>image_raw</imageTopicName>
        <cameraInfoTopicName>camera_info</cameraInfoTopicName>
        <frameName>right_door_anchor_camera_link</frameName>
        <robotNamespace>/navya_bus</robotNamespace>
        <hackBaseline>0.07</hackBaseline>
        <distortionK1>0.0</distortionK1>
        <distortionK2>0.0</distortionK2>
        <distortionK3>0.0</distortionK3>
        <distortionT1>0.0</distortionT1>
        <distortionT2>0.0</distortionT2>
      </plugin>
    </sensor>
  </gazebo>
  <!--xacro:my_camera parent="${lr}_door" pos="${lr}_door"
   rX="1" rY="0" rZ="0" tX="0" tY="${-0.05}" tZ="0"
   fX="${rcX}" fY="${rcY}" fZ="${rcZ}"/-->
  <joint name="right_door_anchor_joint" type="prismatic">
    <parent link="base_link"/>
    <child link="right_door_anchor"/>
    <axis xyz="-1 0 0"/>
    <!-- door opens by itself so closing it here -->
    <!--limit effort="0" velocity="0.0" friction="100.0" lower="0" upper="${l}"/-->
    <limit effort="10000" friction="1000.0" lower="0" upper="0" velocity=".50"/>
    <origin rpy="0.0 0.0 0.0" xyz="-0.01 -1.025 0.3301"/>
    <!--origin xyz="0 0 0" rpy="0 0 0" /-->
  </joint>
  <transmission name="right_door_anchor_joint_trans">
    <type>transmission_interface/SimpleTransmission</type>
    <joint name="right_door_anchor_joint">
      <hardwareInterface>hardware_interface/EffortJointInterface</hardwareInterface>
    </joint>
    <actuator name="right_door_anchor_joint_motor">
      <hardwareInterface>EffortJointInterface</hardwareInterface>
      <mechanicalReduction>1</mechanicalReduction>
    </actuator>
  </transmission>
  <!--lr : left,right-->
  <link name="left_door">
    <visual>
      <geometry>
        <box size="0.702 2.1 0.05"/>
      </geometry>
      <material name="Blue"/>
    </visual>
    <collision>
      <geometry>
        <box size="0.702 2.1 0.05"/>
      </geometry>
    </collision>
    <origin rpy="0 0 0" xyz="0 0 0.029335"/>
    <inertial>
      <mass value="12.0"/>
      <inertia ixx="4.4125" ixy="0.0" ixz="0.0" iyy="0.495304" iyz="0.0" izz="4.902804"/>
    </inertial>
  </link>
  <gazebo reference="left_door">
    <material>Gazebo/Blue</material>
  </gazebo>
  <link name="left_door_camera_link">
    <origin rpy="0 0 0" xyz="0 0 0.029335"/>
    <inertial>
      <mass value="0.1"/>
      <inertia ixx="1.66666666667e-06" ixy="0.0" ixz="0.0" iyy="1.66666666667e-06" iyz="0.0" izz="1.66666666667e-06"/>
    </inertial>
    <collision>
      <origin rpy="0 0 0" xyz="0 0 0"/>
      <geometry>
        <box size="0.02 0.02 0.02"/>
      </geometry>
    </collision>
    <visual>
      <origin rpy="0 0 0" xyz="0 0 0"/>
      <geometry>
        <box size="0.02 0.02 0.02"/>
      </geometry>
      <material name="red"/>
    </visual>
    <origin rpy="0 0 0" xyz="0 0 0.029335"/>
    <inertial>
      <mass value="1e-06"/>
      <inertia ixx="6.66666666667e-11" ixy="0.0" ixz="0.0" iyy="6.66666666667e-11" iyz="0.0" izz="6.66666666667e-11"/>
    </inertial>
  </link>
  <joint name="left_door_camera_joint" type="revolute">
    <parent link="left_door"/>
    <child link="left_door_camera_link"/>
    <origin rpy="-1.570796327 1.570796327 0.0" xyz="0.03 0 0"/>
    <axis xyz="0 0 -1"/>
    <limit effort="20" friction="20.0" lower="0" upper="0" velocity="0.11111"/>
  </joint>
  <transmission name="left_door_camera_joint_trans">
    <type>transmission_interface/SimpleTransmission</type>
    <joint name="left_door_camera_joint">
      <hardwareInterface>hardware_interface/EffortJointInterface</hardwareInterface>
    </joint>
    <actuator name="left_door_camera_joint_motor">
      <hardwareInterface>EffortJointInterface</hardwareInterface>
      <mechanicalReduction>1</mechanicalReduction>
    </actuator>
  </transmission>
  <gazebo reference="left_door_camera_link">
    <sensor name="left_door_camera" type="camera">
      <update_rate>30.0</update_rate>
      <camera name="left_door">
        <!--visualize>true</visualize-->
        <horizontal_fov>1.3962634</horizontal_fov>
        <image>
          <width>800</width>
          <height>800</height>
          <format>R8G8B8</format>
        </image>
        <clip>
          <near>0.02</near>
          <far>300</far>
        </clip>
        <noise>
          <type>gaussian</type>
          <!-- Noise is sampled independently per pixel on each frame.
               That pixel's noise value is added to each of its color
               channels, which at that point lie in the range [0,1]. -->
          <mean>0.0</mean>
          <stddev>0.007</stddev>
        </noise>
      </camera>
      <plugin filename="libgazebo_ros_camera.so" name="camera_controller">
        <material>Gazebo/Gold</material>
        <alwaysOn>true</alwaysOn>
        <updateRate>30.0</updateRate>
        <visualize>true</visualize>
        <cameraName>left_door_camera</cameraName>
        <imageTopicName>image_raw</imageTopicName>
        <cameraInfoTopicName>camera_info</cameraInfoTopicName>
        <frameName>left_door_camera_link</frameName>
        <robotNamespace>/navya_bus</robotNamespace>
        <hackBaseline>0.07</hackBaseline>
        <distortionK1>0.0</distortionK1>
        <distortionK2>0.0</distortionK2>
        <distortionK3>0.0</distortionK3>
        <distortionT1>0.0</distortionT1>
        <distortionT2>0.0</distortionT2>
      </plugin>
    </sensor>
  </gazebo>
  <!--xacro:laser name="${lr}_door" rX="0" rY="0" rZ="1" tZ="0.0" par="${lr}_door"
   fX="0" fY=".5" fZ="0"/-->
  <joint name="left_door_joint" type="prismatic">
    <parent link="left_door_anchor"/>
    <child link="left_door"/>
    <!--origin xyz="0 0 0" rpy="0 0 0"/-->
    <origin rpy="1.570796327 0.0  0 " xyz="0 0 1.05"/>
    <axis xyz="0 0 -1"/>
    <limit effort="100" lower="-0.06" upper="0" velocity="0.08"/>
    <joint_properties damping="1000.0" friction="100.0"/>
  </joint>
  <!-- Transmission is important to link the joints and the controller -->
  <transmission name="left_door_joint_trans">
    <type>transmission_interface/SimpleTransmission</type>
    <joint name="left_door_joint">
      <hardwareInterface>hardware_interface/PositionJointInterface</hardwareInterface>
    </joint>
    <actuator name="left_door_joint_motor">
      <hardwareInterface>PositionJointInterface</hardwareInterface>
      <mechanicalReduction>1</mechanicalReduction>
    </actuator>
  </transmission>
  <!--lr : left,right-->
  <link name="right_door">
    <visual>
      <geometry>
        <box size="0.702 2.1 0.05"/>
      </geometry>
      <material name="Blue"/>
    </visual>
    <collision>
      <geometry>
        <box size="0.702 2.1 0.05"/>
      </geometry>
    </collision>
    <origin rpy="0 0 0" xyz="0 0 0.029335"/>
    <inertial>
      <mass value="12.0"/>
      <inertia ixx="4.4125" ixy="0.0" ixz="0.0" iyy="0.495304" iyz="0.0" izz="4.902804"/>
    </inertial>
  </link>
  <gazebo reference="right_door">
    <material>Gazebo/Blue</material>
  </gazebo>
  <link name="right_door_camera_link">
    <origin rpy="0 0 0" xyz="0 0 0.029335"/>
    <inertial>
      <mass value="0.1"/>
      <inertia ixx="1.66666666667e-06" ixy="0.0" ixz="0.0" iyy="1.66666666667e-06" iyz="0.0" izz="1.66666666667e-06"/>
    </inertial>
    <collision>
      <origin rpy="0 0 0" xyz="0 0 0"/>
      <geometry>
        <box size="0.02 0.02 0.02"/>
      </geometry>
    </collision>
    <visual>
      <origin rpy="0 0 0" xyz="0 0 0"/>
      <geometry>
        <box size="0.02 0.02 0.02"/>
      </geometry>
      <material name="red"/>
    </visual>
    <origin rpy="0 0 0" xyz="0 0 0.029335"/>
    <inertial>
      <mass value="1e-06"/>
      <inertia ixx="6.66666666667e-11" ixy="0.0" ixz="0.0" iyy="6.66666666667e-11" iyz="0.0" izz="6.66666666667e-11"/>
    </inertial>
  </link>
  <joint name="right_door_camera_joint" type="revolute">
    <parent link="right_door"/>
    <child link="right_door_camera_link"/>
    <origin rpy="-1.570796327 -1.570796327 0.0" xyz="-0.03 0 0"/>
    <axis xyz="0 0 1"/>
    <limit effort="20" friction="20.0" lower="0" upper="0" velocity="0.11111"/>
  </joint>
  <transmission name="right_door_camera_joint_trans">
    <type>transmission_interface/SimpleTransmission</type>
    <joint name="right_door_camera_joint">
      <hardwareInterface>hardware_interface/EffortJointInterface</hardwareInterface>
    </joint>
    <actuator name="right_door_camera_joint_motor">
      <hardwareInterface>EffortJointInterface</hardwareInterface>
      <mechanicalReduction>1</mechanicalReduction>
    </actuator>
  </transmission>
  <gazebo reference="right_door_camera_link">
    <sensor name="right_door_camera" type="camera">
      <update_rate>30.0</update_rate>
      <camera name="right_door">
        <!--visualize>true</visualize-->
        <horizontal_fov>1.3962634</horizontal_fov>
        <image>
          <width>800</width>
          <height>800</height>
          <format>R8G8B8</format>
        </image>
        <clip>
          <near>0.02</near>
          <far>300</far>
        </clip>
        <noise>
          <type>gaussian</type>
          <!-- Noise is sampled independently per pixel on each frame.
               That pixel's noise value is added to each of its color
               channels, which at that point lie in the range [0,1]. -->
          <mean>0.0</mean>
          <stddev>0.007</stddev>
        </noise>
      </camera>
      <plugin filename="libgazebo_ros_camera.so" name="camera_controller">
        <material>Gazebo/Gold</material>
        <alwaysOn>true</alwaysOn>
        <updateRate>30.0</updateRate>
        <visualize>true</visualize>
        <cameraName>right_door_camera</cameraName>
        <imageTopicName>image_raw</imageTopicName>
        <cameraInfoTopicName>camera_info</cameraInfoTopicName>
        <frameName>right_door_camera_link</frameName>
        <robotNamespace>/navya_bus</robotNamespace>
        <hackBaseline>0.07</hackBaseline>
        <distortionK1>0.0</distortionK1>
        <distortionK2>0.0</distortionK2>
        <distortionK3>0.0</distortionK3>
        <distortionT1>0.0</distortionT1>
        <distortionT2>0.0</distortionT2>
      </plugin>
    </sensor>
  </gazebo>
  <!--xacro:laser name="${lr}_door" rX="0" rY="0" rZ="1" tZ="0.0" par="${lr}_door"
   fX="0" fY=".5" fZ="0"/-->
  <joint name="right_door_joint" type="prismatic">
    <parent link="right_door_anchor"/>
    <child link="right_door"/>
    <!--origin xyz="0 0 0" rpy="0 0 0"/-->
    <origin rpy="1.570796327 0.0  0 " xyz="0 0 1.05"/>
    <axis xyz="0 0 1"/>
    <limit effort="100" lower="-0.06" upper="0" velocity="0.08"/>
    <joint_properties damping="1000.0" friction="100.0"/>
  </joint>
  <!-- Transmission is important to link the joints and the controller -->
  <transmission name="right_door_joint_trans">
    <type>transmission_interface/SimpleTransmission</type>
    <joint name="right_door_joint">
      <hardwareInterface>hardware_interface/PositionJointInterface</hardwareInterface>
    </joint>
    <actuator name="right_door_joint_motor">
      <hardwareInterface>PositionJointInterface</hardwareInterface>
      <mechanicalReduction>1</mechanicalReduction>
    </actuator>
  </transmission>
  <!-- NOW WE ADD THE DOOR HANDLES -->
  <link name="left_door_handle">
    <!--origin xyz="${tX} ${tY} ${tZ}" rpy="0 0 0"/-->
    <visual>
      <geometry>
        <box size="0.12 0.14 0.06"/>
        <!--mesh filename="~/.gazebo/models/pioneer2dx/meshes/darlingtons_car_handle.dae">
			<scale>${w} ${l} ${h}</scale>
			</mesh-->
      </geometry>
      <material name="Wood"/>
    </visual>
    <collision>
      <geometry>
        <box size="0.12 0.14 0.06"/>
      </geometry>
    </collision>
    <origin rpy="0 0 0" xyz="0 0 0.029335"/>
    <inertial>
      <mass value="1.2"/>
      <inertia ixx="0.00232" ixy="0.0" ixz="0.0" iyy="0.0018" iyz="0.0" izz="0.0034"/>
    </inertial>
  </link>
  <gazebo reference="left_door_handle">
    <material>Gazebo/Wood</material>
  </gazebo>
  <joint name="left_door_handle_joint" type="prismatic">
    <parent link="left_door"/>
    <child link="left_door_handle"/>
    <axis xyz="0 0 1"/>
    <origin rpy="1.570796327 0 0" xyz="0.29 -0.5 0.0"/>
    <limit effort="10" friction="120.0" lower="-0.04" upper="0.06" velocity="0.0"/>
  </joint>
  <!-- Transmission is important to link the joints and the controller -->
  <transmission name="left_door_handle_joint_trans">
    <type>transmission_interface/SimpleTransmission</type>
    <joint name="left_door_handle_joint">
      <hardwareInterface>hardware_interface/PositionJointInterface</hardwareInterface>
    </joint>
    <actuator name="left_door_handle_joint_motor">
      <hardwareInterface>PositionJointInterface</hardwareInterface>
      <mechanicalReduction>1</mechanicalReduction>
    </actuator>
  </transmission>
  <link name="right_door_handle">
    <!--origin xyz="${tX} ${tY} ${tZ}" rpy="0 0 0"/-->
    <visual>
      <geometry>
        <box size="0.12 0.14 0.06"/>
        <!--mesh filename="~/.gazebo/models/pioneer2dx/meshes/darlingtons_car_handle.dae">
			<scale>${w} ${l} ${h}</scale>
			</mesh-->
      </geometry>
      <material name="Wood"/>
    </visual>
    <collision>
      <geometry>
        <box size="0.12 0.14 0.06"/>
      </geometry>
    </collision>
    <origin rpy="0 0 0" xyz="0 0 0.029335"/>
    <inertial>
      <mass value="1.2"/>
      <inertia ixx="0.00232" ixy="0.0" ixz="0.0" iyy="0.0018" iyz="0.0" izz="0.0034"/>
    </inertial>
  </link>
  <gazebo reference="right_door_handle">
    <material>Gazebo/Wood</material>
  </gazebo>
  <joint name="right_door_handle_joint" type="prismatic">
    <parent link="right_door"/>
    <child link="right_door_handle"/>
    <axis xyz="0 0 1"/>
    <origin rpy="1.570796327 0 0" xyz="0.29 -0.5 0.0"/>
    <limit effort="10" friction="120.0" lower="-0.04" upper="0.06" velocity="0.0"/>
  </joint>
  <!-- Transmission is important to link the joints and the controller -->
  <transmission name="right_door_handle_joint_trans">
    <type>transmission_interface/SimpleTransmission</type>
    <joint name="right_door_handle_joint">
      <hardwareInterface>hardware_interface/PositionJointInterface</hardwareInterface>
    </joint>
    <actuator name="right_door_handle_joint_motor">
      <hardwareInterface>PositionJointInterface</hardwareInterface>
      <mechanicalReduction>1</mechanicalReduction>
    </actuator>
  </transmission>
  <gazebo>
    <plugin filename="libgazebo_ros_control.so" name="gazebo_ros_control">
      <robotNamespace>/navya_bus</robotNamespace>
      <robotSimType>gazebo_ros_control/DefaultRobotHWSim</robotSimType>
      <robotBaseFrame>base_link</robotBaseFrame>
      <!--commandTopic>cmd_vel</commandTopic>
      <odometryTopic>odom</odometryTopic>
      <odometryFrame>odom</odometryFrame>
      <odometryRate>20.0</odometryRate-->
    </plugin>
  </gazebo>
  <gazebo>
    <plugin filename="/home/darling/Desktop/navya_working_copy/devel/lib/libvehicle_driver.so" name="vehicle_driver"/>
  </gazebo>
</robot>

